2018-11-05 17:33:03,729 - [INFO] __main__ [app_api, line 31]: ================================================================
2018-11-05 17:33:03,730 - [INFO] __main__ [app_api, line 32]: ================================================================
2018-11-05 17:33:03,730 - [INFO] __main__ [app_api, line 33]: ================================================================
2018-11-05 17:33:03,730 - [INFO] __main__ [app_api, line 34]: Initialising app
2018-11-05 17:33:15,980 - [INFO] __main__ [app_api, line 31]: ================================================================
2018-11-05 17:33:15,980 - [INFO] __main__ [app_api, line 32]: ================================================================
2018-11-05 17:33:15,980 - [INFO] __main__ [app_api, line 33]: ================================================================
2018-11-05 17:33:15,981 - [INFO] __main__ [app_api, line 34]: Initialising app
2018-11-05 17:33:16,001 - [INFO] werkzeug [_internal, line 88]:  * Running on http://127.0.0.1:6500/ (Press CTRL+C to quit)
2018-11-05 17:33:16,002 - [INFO] werkzeug [_internal, line 88]:  * Restarting with stat
2018-11-05 17:33:16,318 - [INFO] __main__ [app_api, line 31]: ================================================================
2018-11-05 17:33:16,318 - [INFO] __main__ [app_api, line 32]: ================================================================
2018-11-05 17:33:16,318 - [INFO] __main__ [app_api, line 33]: ================================================================
2018-11-05 17:33:16,318 - [INFO] __main__ [app_api, line 34]: Initialising app
2018-11-05 17:33:16,328 - [WARNING] werkzeug [_internal, line 88]:  * Debugger is active!
2018-11-05 17:33:16,353 - [INFO] werkzeug [_internal, line 88]:  * Debugger PIN: 262-750-570
2018-11-05 17:34:50,077 - [INFO] werkzeug [_internal, line 88]: 127.0.0.1 - - [05/Nov/2018 17:34:50] "GET / HTTP/1.1" 200 -
2018-11-05 17:34:50,126 - [INFO] werkzeug [_internal, line 88]: 127.0.0.1 - - [05/Nov/2018 17:34:50] "GET /swaggerui/droid-sans.css HTTP/1.1" 200 -
2018-11-05 17:34:50,130 - [INFO] werkzeug [_internal, line 88]: 127.0.0.1 - - [05/Nov/2018 17:34:50] "GET /swaggerui/swagger-ui-bundle.js HTTP/1.1" 200 -
2018-11-05 17:34:50,131 - [INFO] werkzeug [_internal, line 88]: 127.0.0.1 - - [05/Nov/2018 17:34:50] "GET /swaggerui/swagger-ui-standalone-preset.js HTTP/1.1" 200 -
2018-11-05 17:34:50,149 - [INFO] werkzeug [_internal, line 88]: 127.0.0.1 - - [05/Nov/2018 17:34:50] "GET /swaggerui/swagger-ui.css HTTP/1.1" 200 -
2018-11-05 17:34:50,757 - [INFO] werkzeug [_internal, line 88]: 127.0.0.1 - - [05/Nov/2018 17:34:50] "GET /swagger.json HTTP/1.1" 200 -
2018-11-05 17:34:50,993 - [INFO] werkzeug [_internal, line 88]: 127.0.0.1 - - [05/Nov/2018 17:34:50] "GET /swaggerui/favicon-32x32.png HTTP/1.1" 200 -
2018-11-05 17:34:50,999 - [INFO] werkzeug [_internal, line 88]: 127.0.0.1 - - [05/Nov/2018 17:34:50] "GET /swaggerui/favicon-16x16.png HTTP/1.1" 200 -
2018-11-05 17:44:45,763 - [INFO] werkzeug [_internal, line 88]:  * Detected change in '/Users/home/Google_Drive/_CODE/python.homemedia_api/api/apis/ns_media_file.py', reloading
2018-11-05 17:44:45,801 - [INFO] werkzeug [_internal, line 88]:  * Restarting with stat
2018-11-05 17:44:46,556 - [INFO] __main__ [app_api, line 31]: ================================================================
2018-11-05 17:44:46,556 - [INFO] __main__ [app_api, line 32]: ================================================================
2018-11-05 17:44:46,557 - [INFO] __main__ [app_api, line 33]: ================================================================
2018-11-05 17:44:46,557 - [INFO] __main__ [app_api, line 34]: Initialising app
2018-11-05 17:44:46,624 - [WARNING] werkzeug [_internal, line 88]:  * Debugger is active!
2018-11-05 17:44:46,667 - [INFO] werkzeug [_internal, line 88]:  * Debugger PIN: 262-750-570
2018-11-05 17:44:49,478 - [INFO] werkzeug [_internal, line 88]: 127.0.0.1 - - [05/Nov/2018 17:44:49] "GET / HTTP/1.1" 200 -
2018-11-05 17:44:49,624 - [INFO] werkzeug [_internal, line 88]: 127.0.0.1 - - [05/Nov/2018 17:44:49] "GET /swagger.json HTTP/1.1" 200 -
2018-11-05 17:44:49,633 - [INFO] werkzeug [_internal, line 88]: 127.0.0.1 - - [05/Nov/2018 17:44:49] "GET /swaggerui/favicon-32x32.png HTTP/1.1" 200 -
2018-11-05 17:45:33,451 - [DEBUG] api.apis.ns_media_file [ns_media_file, line 326]: path: test.CR2
2018-11-05 17:45:33,451 - [DEBUG] api.apis.ns_media_file [ns_media_file, line 34]: New MediaFile, path: test.CR2
2018-11-05 17:45:33,452 - [DEBUG] api.apis.ns_media_file [ns_media_file, line 332]: api.payload: None
2018-11-05 17:45:33,452 - [ERROR] api.apis [__init__, line 24]: 'NoneType' object has no attribute 'keys'
Traceback (most recent call last):
  File "/Users/home/Google_Drive/_CODE/python.homemedia_api/venv/lib/python2.7/site-packages/flask/app.py", line 1813, in full_dispatch_request
    rv = self.dispatch_request()
  File "/Users/home/Google_Drive/_CODE/python.homemedia_api/venv/lib/python2.7/site-packages/flask/app.py", line 1799, in dispatch_request
    return self.view_functions[rule.endpoint](**req.view_args)
  File "/Users/home/Google_Drive/_CODE/python.homemedia_api/venv/lib/python2.7/site-packages/flask_restplus/api.py", line 325, in wrapper
    resp = resource(*args, **kwargs)
  File "/Users/home/Google_Drive/_CODE/python.homemedia_api/venv/lib/python2.7/site-packages/flask/views.py", line 88, in view
    return self.dispatch_request(*args, **kwargs)
  File "/Users/home/Google_Drive/_CODE/python.homemedia_api/venv/lib/python2.7/site-packages/flask_restplus/resource.py", line 44, in dispatch_request
    resp = meth(*args, **kwargs)
  File "/Users/home/Google_Drive/_CODE/python.homemedia_api/api/apis/ns_media_file.py", line 333, in put
    for key in api.payload.keys():
AttributeError: 'NoneType' object has no attribute 'keys'
2018-11-05 17:45:33,457 - [ERROR] api.apis [__init__, line 24]: 
Traceback (most recent call last):
  File "/Users/home/Google_Drive/_CODE/python.homemedia_api/venv/lib/python2.7/site-packages/flask/app.py", line 2292, in wsgi_app
    response = self.full_dispatch_request()
  File "/Users/home/Google_Drive/_CODE/python.homemedia_api/venv/lib/python2.7/site-packages/flask/app.py", line 1815, in full_dispatch_request
    rv = self.handle_user_exception(e)
  File "/Users/home/Google_Drive/_CODE/python.homemedia_api/venv/lib/python2.7/site-packages/flask_restplus/api.py", line 583, in error_router
    return original_handler(e)
  File "/Users/home/Google_Drive/_CODE/python.homemedia_api/venv/lib/python2.7/site-packages/flask_cors/extension.py", line 161, in wrapped_function
    return cors_after_request(app.make_response(f(*args, **kwargs)))
  File "/Users/home/Google_Drive/_CODE/python.homemedia_api/venv/lib/python2.7/site-packages/flask/app.py", line 1695, in handle_user_exception
    assert exc_value is e
AssertionError
2018-11-05 17:45:33,466 - [INFO] werkzeug [_internal, line 88]: 127.0.0.1 - - [05/Nov/2018 17:45:33] "PUT /mediafile/content/test.CR2 HTTP/1.1" 500 -
2018-11-05 17:47:49,188 - [INFO] werkzeug [_internal, line 88]:  * Detected change in '/Users/home/Google_Drive/_CODE/python.homemedia_api/api/apis/ns_media_file.py', reloading
2018-11-05 17:47:49,213 - [INFO] werkzeug [_internal, line 88]:  * Restarting with stat
2018-11-05 17:47:49,823 - [INFO] __main__ [app_api, line 31]: ================================================================
2018-11-05 17:47:49,824 - [INFO] __main__ [app_api, line 32]: ================================================================
2018-11-05 17:47:49,825 - [INFO] __main__ [app_api, line 33]: ================================================================
2018-11-05 17:47:49,825 - [INFO] __main__ [app_api, line 34]: Initialising app
2018-11-05 17:47:49,867 - [WARNING] werkzeug [_internal, line 88]:  * Debugger is active!
2018-11-05 17:47:49,889 - [INFO] werkzeug [_internal, line 88]:  * Debugger PIN: 262-750-570
2018-11-05 17:47:52,496 - [DEBUG] api.apis.ns_media_file [ns_media_file, line 326]: path: test.CR2
2018-11-05 17:47:52,496 - [DEBUG] api.apis.ns_media_file [ns_media_file, line 34]: New MediaFile, path: test.CR2
2018-11-05 17:47:52,496 - [DEBUG] api.apis.ns_media_file [ns_media_file, line 332]: api.payload: None
2018-11-05 17:47:52,497 - [ERROR] api.apis [__init__, line 24]: 'NoneType' object has no attribute 'keys'
Traceback (most recent call last):
  File "/Users/home/Google_Drive/_CODE/python.homemedia_api/venv/lib/python2.7/site-packages/flask/app.py", line 1813, in full_dispatch_request
    rv = self.dispatch_request()
  File "/Users/home/Google_Drive/_CODE/python.homemedia_api/venv/lib/python2.7/site-packages/flask/app.py", line 1799, in dispatch_request
    return self.view_functions[rule.endpoint](**req.view_args)
  File "/Users/home/Google_Drive/_CODE/python.homemedia_api/venv/lib/python2.7/site-packages/flask_restplus/api.py", line 325, in wrapper
    resp = resource(*args, **kwargs)
  File "/Users/home/Google_Drive/_CODE/python.homemedia_api/venv/lib/python2.7/site-packages/flask/views.py", line 88, in view
    return self.dispatch_request(*args, **kwargs)
  File "/Users/home/Google_Drive/_CODE/python.homemedia_api/venv/lib/python2.7/site-packages/flask_restplus/resource.py", line 44, in dispatch_request
    resp = meth(*args, **kwargs)
  File "/Users/home/Google_Drive/_CODE/python.homemedia_api/api/apis/ns_media_file.py", line 334, in put
    for key in api.payload.keys():
AttributeError: 'NoneType' object has no attribute 'keys'
2018-11-05 17:47:52,498 - [ERROR] api.apis [__init__, line 24]: 
Traceback (most recent call last):
  File "/Users/home/Google_Drive/_CODE/python.homemedia_api/venv/lib/python2.7/site-packages/flask/app.py", line 2292, in wsgi_app
    response = self.full_dispatch_request()
  File "/Users/home/Google_Drive/_CODE/python.homemedia_api/venv/lib/python2.7/site-packages/flask/app.py", line 1815, in full_dispatch_request
    rv = self.handle_user_exception(e)
  File "/Users/home/Google_Drive/_CODE/python.homemedia_api/venv/lib/python2.7/site-packages/flask_restplus/api.py", line 583, in error_router
    return original_handler(e)
  File "/Users/home/Google_Drive/_CODE/python.homemedia_api/venv/lib/python2.7/site-packages/flask_cors/extension.py", line 161, in wrapped_function
    return cors_after_request(app.make_response(f(*args, **kwargs)))
  File "/Users/home/Google_Drive/_CODE/python.homemedia_api/venv/lib/python2.7/site-packages/flask/app.py", line 1695, in handle_user_exception
    assert exc_value is e
AssertionError
2018-11-05 17:47:52,506 - [INFO] werkzeug [_internal, line 88]: 127.0.0.1 - - [05/Nov/2018 17:47:52] "PUT /mediafile/content/test.CR2 HTTP/1.1" 500 -
2018-11-05 17:48:14,574 - [INFO] __main__ [app_api, line 31]: ================================================================
2018-11-05 17:48:14,575 - [INFO] __main__ [app_api, line 32]: ================================================================
2018-11-05 17:48:14,575 - [INFO] __main__ [app_api, line 33]: ================================================================
2018-11-05 17:48:14,575 - [INFO] __main__ [app_api, line 34]: Initialising app
2018-11-05 17:48:14,593 - [INFO] werkzeug [_internal, line 88]:  * Running on http://127.0.0.1:6500/ (Press CTRL+C to quit)
2018-11-05 17:48:14,595 - [INFO] werkzeug [_internal, line 88]:  * Restarting with stat
2018-11-05 17:48:14,872 - [INFO] __main__ [app_api, line 31]: ================================================================
2018-11-05 17:48:14,872 - [INFO] __main__ [app_api, line 32]: ================================================================
2018-11-05 17:48:14,872 - [INFO] __main__ [app_api, line 33]: ================================================================
2018-11-05 17:48:14,872 - [INFO] __main__ [app_api, line 34]: Initialising app
2018-11-05 17:48:14,882 - [WARNING] werkzeug [_internal, line 88]:  * Debugger is active!
2018-11-05 17:48:14,896 - [INFO] werkzeug [_internal, line 88]:  * Debugger PIN: 262-750-570
2018-11-05 17:48:18,291 - [DEBUG] api.apis.ns_media_file [ns_media_file, line 326]: path: test.CR2
2018-11-05 17:48:18,292 - [DEBUG] api.apis.ns_media_file [ns_media_file, line 34]: New MediaFile, path: test.CR2
2018-11-05 17:48:18,292 - [DEBUG] api.apis.ns_media_file [ns_media_file, line 332]: api.payload: None
2018-11-05 17:48:18,292 - [ERROR] api.apis [__init__, line 24]: 'NoneType' object has no attribute 'keys'
Traceback (most recent call last):
  File "/Users/home/Google_Drive/_CODE/python.homemedia_api/venv/lib/python2.7/site-packages/flask/app.py", line 1813, in full_dispatch_request
    rv = self.dispatch_request()
  File "/Users/home/Google_Drive/_CODE/python.homemedia_api/venv/lib/python2.7/site-packages/flask/app.py", line 1799, in dispatch_request
    return self.view_functions[rule.endpoint](**req.view_args)
  File "/Users/home/Google_Drive/_CODE/python.homemedia_api/venv/lib/python2.7/site-packages/flask_restplus/api.py", line 325, in wrapper
    resp = resource(*args, **kwargs)
  File "/Users/home/Google_Drive/_CODE/python.homemedia_api/venv/lib/python2.7/site-packages/flask/views.py", line 88, in view
    return self.dispatch_request(*args, **kwargs)
  File "/Users/home/Google_Drive/_CODE/python.homemedia_api/venv/lib/python2.7/site-packages/flask_restplus/resource.py", line 44, in dispatch_request
    resp = meth(*args, **kwargs)
  File "/Users/home/Google_Drive/_CODE/python.homemedia_api/api/apis/ns_media_file.py", line 334, in put
    for key in api.payload.keys():
AttributeError: 'NoneType' object has no attribute 'keys'
2018-11-05 17:48:18,294 - [ERROR] api.apis [__init__, line 24]: 
Traceback (most recent call last):
  File "/Users/home/Google_Drive/_CODE/python.homemedia_api/venv/lib/python2.7/site-packages/flask/app.py", line 2292, in wsgi_app
    response = self.full_dispatch_request()
  File "/Users/home/Google_Drive/_CODE/python.homemedia_api/venv/lib/python2.7/site-packages/flask/app.py", line 1815, in full_dispatch_request
    rv = self.handle_user_exception(e)
  File "/Users/home/Google_Drive/_CODE/python.homemedia_api/venv/lib/python2.7/site-packages/flask_restplus/api.py", line 583, in error_router
    return original_handler(e)
  File "/Users/home/Google_Drive/_CODE/python.homemedia_api/venv/lib/python2.7/site-packages/flask_cors/extension.py", line 161, in wrapped_function
    return cors_after_request(app.make_response(f(*args, **kwargs)))
  File "/Users/home/Google_Drive/_CODE/python.homemedia_api/venv/lib/python2.7/site-packages/flask/app.py", line 1695, in handle_user_exception
    assert exc_value is e
AssertionError
2018-11-05 17:48:18,301 - [INFO] werkzeug [_internal, line 88]: 127.0.0.1 - - [05/Nov/2018 17:48:18] "PUT /mediafile/content/test.CR2 HTTP/1.1" 500 -
2018-11-05 17:50:42,973 - [INFO] werkzeug [_internal, line 88]:  * Detected change in '/Users/home/Google_Drive/_CODE/python.homemedia_api/api/apis/ns_media_file.py', reloading
2018-11-05 17:50:42,999 - [INFO] werkzeug [_internal, line 88]:  * Restarting with stat
2018-11-05 17:50:43,384 - [INFO] __main__ [app_api, line 31]: ================================================================
2018-11-05 17:50:43,385 - [INFO] __main__ [app_api, line 32]: ================================================================
2018-11-05 17:50:43,385 - [INFO] __main__ [app_api, line 33]: ================================================================
2018-11-05 17:50:43,385 - [INFO] __main__ [app_api, line 34]: Initialising app
2018-11-05 17:50:43,395 - [WARNING] werkzeug [_internal, line 88]:  * Debugger is active!
2018-11-05 17:50:43,435 - [INFO] werkzeug [_internal, line 88]:  * Debugger PIN: 262-750-570
2018-11-05 17:53:23,059 - [INFO] werkzeug [_internal, line 88]:  * Detected change in '/Users/home/Google_Drive/_CODE/python.homemedia_api/api/apis/ns_media_file.py', reloading
2018-11-05 17:53:23,093 - [INFO] werkzeug [_internal, line 88]:  * Restarting with stat
2018-11-05 17:53:23,439 - [INFO] __main__ [app_api, line 31]: ================================================================
2018-11-05 17:53:23,439 - [INFO] __main__ [app_api, line 32]: ================================================================
2018-11-05 17:53:23,439 - [INFO] __main__ [app_api, line 33]: ================================================================
2018-11-05 17:53:23,439 - [INFO] __main__ [app_api, line 34]: Initialising app
2018-11-05 17:53:23,452 - [WARNING] werkzeug [_internal, line 88]:  * Debugger is active!
2018-11-05 17:53:23,468 - [INFO] werkzeug [_internal, line 88]:  * Debugger PIN: 262-750-570
2018-11-05 17:53:27,407 - [INFO] werkzeug [_internal, line 88]: 127.0.0.1 - - [05/Nov/2018 17:53:27] "GET / HTTP/1.1" 200 -
2018-11-05 17:53:27,912 - [INFO] werkzeug [_internal, line 88]: 127.0.0.1 - - [05/Nov/2018 17:53:27] "GET /swagger.json HTTP/1.1" 200 -
2018-11-05 17:53:27,933 - [INFO] werkzeug [_internal, line 88]: 127.0.0.1 - - [05/Nov/2018 17:53:27] "GET /swaggerui/favicon-32x32.png HTTP/1.1" 200 -
2018-11-05 17:54:53,252 - [INFO] werkzeug [_internal, line 88]:  * Detected change in '/Users/home/Google_Drive/_CODE/python.homemedia_api/api/apis/ns_media_file.py', reloading
2018-11-05 17:54:53,287 - [INFO] werkzeug [_internal, line 88]:  * Restarting with stat
2018-11-05 17:54:54,137 - [INFO] __main__ [app_api, line 31]: ================================================================
2018-11-05 17:54:54,137 - [INFO] __main__ [app_api, line 32]: ================================================================
2018-11-05 17:54:54,137 - [INFO] __main__ [app_api, line 33]: ================================================================
2018-11-05 17:54:54,137 - [INFO] __main__ [app_api, line 34]: Initialising app
2018-11-05 17:54:54,159 - [WARNING] werkzeug [_internal, line 88]:  * Debugger is active!
2018-11-05 17:54:54,192 - [INFO] werkzeug [_internal, line 88]:  * Debugger PIN: 262-750-570
2018-11-05 17:54:56,754 - [INFO] werkzeug [_internal, line 88]: 127.0.0.1 - - [05/Nov/2018 17:54:56] "GET / HTTP/1.1" 200 -
2018-11-05 17:54:57,161 - [INFO] werkzeug [_internal, line 88]: 127.0.0.1 - - [05/Nov/2018 17:54:57] "GET /swagger.json HTTP/1.1" 200 -
2018-11-05 17:54:57,191 - [INFO] werkzeug [_internal, line 88]: 127.0.0.1 - - [05/Nov/2018 17:54:57] "GET /swaggerui/favicon-32x32.png HTTP/1.1" 200 -
2018-11-05 17:55:13,734 - [DEBUG] api.apis.ns_media_file [ns_media_file, line 320]: path: test.CR2
2018-11-05 17:55:13,734 - [DEBUG] api.apis.ns_media_file [ns_media_file, line 34]: New MediaFile, path: test.CR2
2018-11-05 17:55:13,735 - [INFO] werkzeug [_internal, line 88]: 127.0.0.1 - - [05/Nov/2018 17:55:13] "PUT /mediafile/content/test.CR2 HTTP/1.1" 200 -
2018-11-05 17:57:19,971 - [INFO] werkzeug [_internal, line 88]:  * Detected change in '/Users/home/Google_Drive/_CODE/python.homemedia_api/api/apis/ns_media_file.py', reloading
2018-11-05 17:57:20,017 - [INFO] werkzeug [_internal, line 88]:  * Restarting with stat
2018-11-05 17:57:20,518 - [INFO] __main__ [app_api, line 31]: ================================================================
2018-11-05 17:57:20,519 - [INFO] __main__ [app_api, line 32]: ================================================================
2018-11-05 17:57:20,519 - [INFO] __main__ [app_api, line 33]: ================================================================
2018-11-05 17:57:20,519 - [INFO] __main__ [app_api, line 34]: Initialising app
2018-11-05 17:57:20,530 - [WARNING] werkzeug [_internal, line 88]:  * Debugger is active!
2018-11-05 17:57:20,544 - [INFO] werkzeug [_internal, line 88]:  * Debugger PIN: 262-750-570
2018-11-05 17:57:23,233 - [INFO] werkzeug [_internal, line 88]: 127.0.0.1 - - [05/Nov/2018 17:57:23] "GET / HTTP/1.1" 200 -
2018-11-05 17:57:23,615 - [INFO] werkzeug [_internal, line 88]: 127.0.0.1 - - [05/Nov/2018 17:57:23] "GET /swagger.json HTTP/1.1" 200 -
2018-11-05 17:57:23,655 - [INFO] werkzeug [_internal, line 88]: 127.0.0.1 - - [05/Nov/2018 17:57:23] "GET /swaggerui/favicon-32x32.png HTTP/1.1" 200 -
2018-11-05 17:58:14,391 - [DEBUG] api.apis.ns_media_folder [ns_media_folder, line 152]: parameters: {}
2018-11-05 17:58:14,391 - [DEBUG] api.apis.ns_media_folder [ns_media_folder, line 158]: path: 
2018-11-05 17:58:14,392 - [INFO] api.core.utils_fs [utils_fs, line 180]: Blacklisted folder: /Users/Home/Pictures/@eadir
2018-11-05 17:58:14,392 - [INFO] api.core.utils_fs [utils_fs, line 180]: Blacklisted folder: /Users/Home/Pictures/.TEST
2018-11-05 17:58:14,392 - [DEBUG] api.apis.ns_media_folder [ns_media_folder, line 71]: mfs: ['/Users/Home/Pictures/test.CR2']
2018-11-05 17:58:14,392 - [DEBUG] api.apis.ns_media_file [ns_media_file, line 126]: New MediaFiles, paths: ['/Users/Home/Pictures/test.CR2']
2018-11-05 17:58:14,392 - [DEBUG] api.apis.ns_media_file [ns_media_file, line 34]: New MediaFile, path: test.CR2
2018-11-05 17:58:14,395 - [DEBUG] api.apis.ns_media_file [ns_media_file, line 158]: URL file path: test.CR2
2018-11-05 17:58:14,395 - [DEBUG] api.apis.ns_media_file [ns_media_file, line 167]: URL file path: test.CR2
2018-11-05 17:58:14,397 - [INFO] werkzeug [_internal, line 88]: 127.0.0.1 - - [05/Nov/2018 17:58:14] "GET /mediafolder/ HTTP/1.1" 200 -
2018-11-05 17:58:44,432 - [DEBUG] api.apis.ns_media_file [ns_media_file, line 325]: path: test.CR2
2018-11-05 17:58:44,432 - [DEBUG] api.apis.ns_media_file [ns_media_file, line 34]: New MediaFile, path: test.CR2
2018-11-05 17:58:44,433 - [INFO] werkzeug [_internal, line 88]: 127.0.0.1 - - [05/Nov/2018 17:58:44] "PUT /mediafile/content/test.CR2 HTTP/1.1" 200 -
2018-11-05 17:59:44,139 - [INFO] werkzeug [_internal, line 88]:  * Detected change in '/Users/home/Google_Drive/_CODE/python.homemedia_api/api/apis/ns_media_file.py', reloading
2018-11-05 17:59:44,193 - [INFO] werkzeug [_internal, line 88]:  * Restarting with stat
2018-11-05 17:59:44,747 - [INFO] __main__ [app_api, line 31]: ================================================================
2018-11-05 17:59:44,747 - [INFO] __main__ [app_api, line 32]: ================================================================
2018-11-05 17:59:44,747 - [INFO] __main__ [app_api, line 33]: ================================================================
2018-11-05 17:59:44,748 - [INFO] __main__ [app_api, line 34]: Initialising app
2018-11-05 17:59:44,758 - [WARNING] werkzeug [_internal, line 88]:  * Debugger is active!
2018-11-05 17:59:44,772 - [INFO] werkzeug [_internal, line 88]:  * Debugger PIN: 262-750-570
2018-11-05 17:59:48,258 - [DEBUG] api.apis.ns_media_file [ns_media_file, line 325]: path: test.CR2
2018-11-05 17:59:48,259 - [DEBUG] api.apis.ns_media_file [ns_media_file, line 34]: New MediaFile, path: test.CR2
2018-11-05 17:59:48,259 - [DEBUG] api.apis.ns_media_file [ns_media_file, line 332]: folderUrl
2018-11-05 17:59:48,261 - [INFO] werkzeug [_internal, line 88]: 127.0.0.1 - - [05/Nov/2018 17:59:48] "PUT /mediafile/content/test.CR2 HTTP/1.1" 200 -
2018-11-05 18:00:28,714 - [INFO] werkzeug [_internal, line 88]:  * Detected change in '/Users/home/Google_Drive/_CODE/python.homemedia_api/api/apis/ns_media_file.py', reloading
2018-11-05 18:00:28,741 - [INFO] werkzeug [_internal, line 88]:  * Restarting with stat
2018-11-05 18:00:29,390 - [INFO] __main__ [app_api, line 31]: ================================================================
2018-11-05 18:00:29,390 - [INFO] __main__ [app_api, line 32]: ================================================================
2018-11-05 18:00:29,390 - [INFO] __main__ [app_api, line 33]: ================================================================
2018-11-05 18:00:29,390 - [INFO] __main__ [app_api, line 34]: Initialising app
2018-11-05 18:00:29,402 - [WARNING] werkzeug [_internal, line 88]:  * Debugger is active!
2018-11-05 18:00:29,421 - [INFO] werkzeug [_internal, line 88]:  * Debugger PIN: 262-750-570
2018-11-05 18:00:31,204 - [DEBUG] api.apis.ns_media_file [ns_media_file, line 325]: path: test.CR2
2018-11-05 18:00:31,204 - [DEBUG] api.apis.ns_media_file [ns_media_file, line 34]: New MediaFile, path: test.CR2
2018-11-05 18:00:31,205 - [DEBUG] api.apis.ns_media_file [ns_media_file, line 331]: payload: {u'folderUrl': u'http://127.0.0.1:6500/mediafolder/Google%20Photos%20Backup'}
2018-11-05 18:00:31,207 - [INFO] werkzeug [_internal, line 88]: 127.0.0.1 - - [05/Nov/2018 18:00:31] "PUT /mediafile/content/test.CR2 HTTP/1.1" 200 -
2018-11-05 18:05:59,390 - [INFO] werkzeug [_internal, line 88]:  * Detected change in '/Users/home/Google_Drive/_CODE/python.homemedia_api/api/apis/ns_media_file.py', reloading
2018-11-05 18:05:59,422 - [INFO] werkzeug [_internal, line 88]:  * Restarting with stat
2018-11-05 18:05:59,870 - [INFO] __main__ [app_api, line 31]: ================================================================
2018-11-05 18:05:59,870 - [INFO] __main__ [app_api, line 32]: ================================================================
2018-11-05 18:05:59,870 - [INFO] __main__ [app_api, line 33]: ================================================================
2018-11-05 18:05:59,870 - [INFO] __main__ [app_api, line 34]: Initialising app
2018-11-05 18:05:59,881 - [WARNING] werkzeug [_internal, line 88]:  * Debugger is active!
2018-11-05 18:05:59,895 - [INFO] werkzeug [_internal, line 88]:  * Debugger PIN: 262-750-570
