2018-11-17 15:21:31,975 - [INFO] __main__ [app_api, line 46]: ================================================================
2018-11-17 15:21:31,976 - [INFO] __main__ [app_api, line 47]: ================================================================
2018-11-17 15:21:31,976 - [INFO] __main__ [app_api, line 48]: ================================================================
2018-11-17 15:21:31,976 - [INFO] __main__ [app_api, line 49]: Initialising app
2018-11-17 15:21:31,987 - [INFO] werkzeug [_internal, line 88]:  * Running on http://127.0.0.1:6500/ (Press CTRL+C to quit)
2018-11-17 15:21:31,988 - [INFO] werkzeug [_internal, line 88]:  * Restarting with stat
2018-11-17 15:21:32,253 - [INFO] __main__ [app_api, line 46]: ================================================================
2018-11-17 15:21:32,253 - [INFO] __main__ [app_api, line 47]: ================================================================
2018-11-17 15:21:32,253 - [INFO] __main__ [app_api, line 48]: ================================================================
2018-11-17 15:21:32,253 - [INFO] __main__ [app_api, line 49]: Initialising app
2018-11-17 15:21:32,264 - [WARNING] werkzeug [_internal, line 88]:  * Debugger is active!
2018-11-17 15:21:32,284 - [INFO] werkzeug [_internal, line 88]:  * Debugger PIN: 449-218-456
2018-11-17 15:21:35,964 - [INFO] werkzeug [_internal, line 88]: 127.0.0.1 - - [17/Nov/2018 15:21:35] "GET / HTTP/1.1" 200 -
2018-11-17 15:21:36,152 - [INFO] werkzeug [_internal, line 88]: 127.0.0.1 - - [17/Nov/2018 15:21:36] "GET /swaggerui/swagger-ui-standalone-preset.js HTTP/1.1" 200 -
2018-11-17 15:21:36,155 - [INFO] werkzeug [_internal, line 88]: 127.0.0.1 - - [17/Nov/2018 15:21:36] "GET /swaggerui/droid-sans.css HTTP/1.1" 200 -
2018-11-17 15:21:36,158 - [INFO] werkzeug [_internal, line 88]: 127.0.0.1 - - [17/Nov/2018 15:21:36] "GET /swaggerui/swagger-ui-bundle.js HTTP/1.1" 200 -
2018-11-17 15:21:36,162 - [INFO] werkzeug [_internal, line 88]: 127.0.0.1 - - [17/Nov/2018 15:21:36] "GET /swaggerui/swagger-ui.css HTTP/1.1" 200 -
2018-11-17 15:21:36,859 - [ERROR] flask_restplus.api [api, line 488]: Unable to render schema
Traceback (most recent call last):
  File "/Users/home/Code/python.homemedia_api/venv/lib/python2.7/site-packages/flask_restplus/api.py", line 483, in __schema__
    self._schema = Swagger(self).as_dict()
  File "/Users/home/Code/python.homemedia_api/venv/lib/python2.7/site-packages/flask_restplus/swagger.py", line 177, in as_dict
    paths[extract_path(url)] = self.serialize_resource(ns, resource, url, kwargs)
  File "/Users/home/Code/python.homemedia_api/venv/lib/python2.7/site-packages/flask_restplus/swagger.py", line 346, in serialize_resource
    path[method] = self.serialize_operation(doc, method)
  File "/Users/home/Code/python.homemedia_api/venv/lib/python2.7/site-packages/flask_restplus/swagger.py", line 352, in serialize_operation
    'responses': self.responses_for(doc, method) or None,
  File "/Users/home/Code/python.homemedia_api/venv/lib/python2.7/site-packages/flask_restplus/swagger.py", line 464, in responses_for
    responses[code]['schema'] = self.serialize_schema(model)
  File "/Users/home/Code/python.homemedia_api/venv/lib/python2.7/site-packages/flask_restplus/swagger.py", line 513, in serialize_schema
    self.register_model(model)
  File "/Users/home/Code/python.homemedia_api/venv/lib/python2.7/site-packages/flask_restplus/swagger.py", line 534, in register_model
    raise ValueError('Model {0} not registered'.format(name))
ValueError: Model init_model not registered
2018-11-17 15:21:36,861 - [INFO] werkzeug [_internal, line 88]: 127.0.0.1 - - [17/Nov/2018 15:21:36] "GET /swagger.json HTTP/1.1" 500 -
2018-11-17 15:24:11,661 - [INFO] __main__ [app_api, line 46]: ================================================================
2018-11-17 15:24:11,661 - [INFO] __main__ [app_api, line 47]: ================================================================
2018-11-17 15:24:11,661 - [INFO] __main__ [app_api, line 48]: ================================================================
2018-11-17 15:24:11,661 - [INFO] __main__ [app_api, line 49]: Initialising app
2018-11-17 15:24:11,677 - [INFO] werkzeug [_internal, line 88]:  * Running on http://127.0.0.1:6500/ (Press CTRL+C to quit)
2018-11-17 15:24:11,678 - [INFO] werkzeug [_internal, line 88]:  * Restarting with stat
2018-11-17 15:24:12,040 - [INFO] __main__ [app_api, line 46]: ================================================================
2018-11-17 15:24:12,041 - [INFO] __main__ [app_api, line 47]: ================================================================
2018-11-17 15:24:12,041 - [INFO] __main__ [app_api, line 48]: ================================================================
2018-11-17 15:24:12,041 - [INFO] __main__ [app_api, line 49]: Initialising app
2018-11-17 15:24:12,056 - [WARNING] werkzeug [_internal, line 88]:  * Debugger is active!
2018-11-17 15:24:12,097 - [INFO] werkzeug [_internal, line 88]:  * Debugger PIN: 449-218-456
2018-11-17 15:24:14,484 - [INFO] werkzeug [_internal, line 88]: 127.0.0.1 - - [17/Nov/2018 15:24:14] "GET / HTTP/1.1" 200 -
2018-11-17 15:24:15,174 - [INFO] werkzeug [_internal, line 88]:  * Detected change in '/Users/home/Code/python.homemedia_api/src/api/restplus.py', reloading
2018-11-17 15:24:15,215 - [INFO] werkzeug [_internal, line 88]:  * Restarting with stat
2018-11-17 15:24:15,837 - [INFO] __main__ [app_api, line 46]: ================================================================
2018-11-17 15:24:15,838 - [INFO] __main__ [app_api, line 47]: ================================================================
2018-11-17 15:24:15,838 - [INFO] __main__ [app_api, line 48]: ================================================================
2018-11-17 15:24:15,838 - [INFO] __main__ [app_api, line 49]: Initialising app
2018-11-17 15:24:15,848 - [WARNING] werkzeug [_internal, line 88]:  * Debugger is active!
2018-11-17 15:24:15,864 - [INFO] werkzeug [_internal, line 88]:  * Debugger PIN: 449-218-456
2018-11-17 15:24:15,884 - [ERROR] flask_restplus.api [api, line 488]: Unable to render schema
Traceback (most recent call last):
  File "/Users/home/Code/python.homemedia_api/venv/lib/python2.7/site-packages/flask_restplus/api.py", line 483, in __schema__
    self._schema = Swagger(self).as_dict()
  File "/Users/home/Code/python.homemedia_api/venv/lib/python2.7/site-packages/flask_restplus/swagger.py", line 177, in as_dict
    paths[extract_path(url)] = self.serialize_resource(ns, resource, url, kwargs)
  File "/Users/home/Code/python.homemedia_api/venv/lib/python2.7/site-packages/flask_restplus/swagger.py", line 346, in serialize_resource
    path[method] = self.serialize_operation(doc, method)
  File "/Users/home/Code/python.homemedia_api/venv/lib/python2.7/site-packages/flask_restplus/swagger.py", line 352, in serialize_operation
    'responses': self.responses_for(doc, method) or None,
  File "/Users/home/Code/python.homemedia_api/venv/lib/python2.7/site-packages/flask_restplus/swagger.py", line 464, in responses_for
    responses[code]['schema'] = self.serialize_schema(model)
  File "/Users/home/Code/python.homemedia_api/venv/lib/python2.7/site-packages/flask_restplus/swagger.py", line 513, in serialize_schema
    self.register_model(model)
  File "/Users/home/Code/python.homemedia_api/venv/lib/python2.7/site-packages/flask_restplus/swagger.py", line 534, in register_model
    raise ValueError('Model {0} not registered'.format(name))
ValueError: Model init_model not registered
2018-11-17 15:24:15,887 - [INFO] werkzeug [_internal, line 88]: 127.0.0.1 - - [17/Nov/2018 15:24:15] "GET /swagger.json HTTP/1.1" 500 -
2018-11-17 15:26:20,646 - [DEBUG] api.endpoints.ns_browse [ns_browse, line 48]: {'path': '', 'include_assets': True, 'flatten_folders': False, 'include_folders': True}
2018-11-17 15:26:20,647 - [INFO] src.api.core.utils_fs [utils_fs, line 227]: Blacklisted folder: /Users/Home/Pictures/@eadir
2018-11-17 15:26:20,647 - [INFO] src.api.core.utils_fs [utils_fs, line 227]: Blacklisted folder: /Users/Home/Pictures/.TEST
2018-11-17 15:26:20,647 - [INFO] src.api.core.utils_fs [utils_fs, line 254]: Blacklisted folder: /Users/Home/Pictures/@eadir
2018-11-17 15:26:20,648 - [INFO] src.api.core.utils_fs [utils_fs, line 254]: Blacklisted folder: /Users/Home/Pictures/.TEST
2018-11-17 15:26:20,668 - [INFO] src.api.core.utils_fs [utils_fs, line 227]: Blacklisted folder: /Users/Home/Pictures/ORIGINALS/Lightroom
2018-11-17 15:26:20,670 - [INFO] werkzeug [_internal, line 88]: 127.0.0.1 - - [17/Nov/2018 15:26:20] "GET /browse HTTP/1.1" 200 -
2018-11-17 15:26:47,911 - [DEBUG] api.endpoints.ns_browse [ns_browse, line 48]: {'path': 'ORIGINALS', 'include_assets': True, 'flatten_folders': False, 'include_folders': True}
2018-11-17 15:26:47,912 - [INFO] src.api.core.utils_fs [utils_fs, line 227]: Blacklisted folder: /Users/Home/Pictures/ORIGINALS/Lightroom
2018-11-17 15:26:47,912 - [INFO] src.api.core.utils_fs [utils_fs, line 254]: Blacklisted folder: /Users/Home/Pictures/ORIGINALS/Lightroom
2018-11-17 15:26:47,918 - [INFO] werkzeug [_internal, line 88]: 127.0.0.1 - - [17/Nov/2018 15:26:47] "GET /browse?path=ORIGINALS HTTP/1.1" 200 -
2018-11-17 15:27:04,663 - [DEBUG] api.endpoints.ns_browse [ns_browse, line 48]: {'path': 'ORIGINALS/test', 'include_assets': True, 'flatten_folders': False, 'include_folders': True}
2018-11-17 15:27:04,665 - [INFO] werkzeug [_internal, line 88]: 127.0.0.1 - - [17/Nov/2018 15:27:04] "GET /browse?path=ORIGINALS/test HTTP/1.1" 200 -
2018-11-17 15:31:41,711 - [INFO] werkzeug [_internal, line 88]:  * Detected change in '/Users/home/Code/python.homemedia_api/src/api/data_models.py', reloading
2018-11-17 15:31:41,815 - [INFO] werkzeug [_internal, line 88]:  * Restarting with stat
2018-11-17 15:32:00,227 - [INFO] __main__ [app_api, line 46]: ================================================================
2018-11-17 15:32:00,227 - [INFO] __main__ [app_api, line 47]: ================================================================
2018-11-17 15:32:00,227 - [INFO] __main__ [app_api, line 48]: ================================================================
2018-11-17 15:32:00,227 - [INFO] __main__ [app_api, line 49]: Initialising app
2018-11-17 15:32:00,239 - [INFO] werkzeug [_internal, line 88]:  * Running on http://127.0.0.1:6500/ (Press CTRL+C to quit)
2018-11-17 15:32:00,240 - [INFO] werkzeug [_internal, line 88]:  * Restarting with stat
2018-11-17 15:32:00,470 - [INFO] __main__ [app_api, line 46]: ================================================================
2018-11-17 15:32:00,471 - [INFO] __main__ [app_api, line 47]: ================================================================
2018-11-17 15:32:00,471 - [INFO] __main__ [app_api, line 48]: ================================================================
2018-11-17 15:32:00,471 - [INFO] __main__ [app_api, line 49]: Initialising app
2018-11-17 15:32:00,481 - [WARNING] werkzeug [_internal, line 88]:  * Debugger is active!
2018-11-17 15:32:00,495 - [INFO] werkzeug [_internal, line 88]:  * Debugger PIN: 449-218-456
2018-11-17 15:32:15,725 - [INFO] werkzeug [_internal, line 88]:  * Detected change in '/Users/home/Code/python.homemedia_api/src/api/data_models.py', reloading
2018-11-17 15:32:15,779 - [INFO] werkzeug [_internal, line 88]:  * Restarting with stat
2018-11-17 15:32:16,683 - [INFO] __main__ [app_api, line 46]: ================================================================
2018-11-17 15:32:16,683 - [INFO] __main__ [app_api, line 47]: ================================================================
2018-11-17 15:32:16,683 - [INFO] __main__ [app_api, line 48]: ================================================================
2018-11-17 15:32:16,683 - [INFO] __main__ [app_api, line 49]: Initialising app
2018-11-17 15:32:16,694 - [WARNING] werkzeug [_internal, line 88]:  * Debugger is active!
2018-11-17 15:32:16,707 - [INFO] werkzeug [_internal, line 88]:  * Debugger PIN: 449-218-456
2018-11-17 15:32:19,124 - [INFO] werkzeug [_internal, line 88]: 127.0.0.1 - - [17/Nov/2018 15:32:19] "GET / HTTP/1.1" 200 -
2018-11-17 15:32:19,720 - [ERROR] flask_restplus.api [api, line 488]: Unable to render schema
Traceback (most recent call last):
  File "/Users/home/Code/python.homemedia_api/venv/lib/python2.7/site-packages/flask_restplus/api.py", line 483, in __schema__
    self._schema = Swagger(self).as_dict()
  File "/Users/home/Code/python.homemedia_api/venv/lib/python2.7/site-packages/flask_restplus/swagger.py", line 177, in as_dict
    paths[extract_path(url)] = self.serialize_resource(ns, resource, url, kwargs)
  File "/Users/home/Code/python.homemedia_api/venv/lib/python2.7/site-packages/flask_restplus/swagger.py", line 346, in serialize_resource
    path[method] = self.serialize_operation(doc, method)
  File "/Users/home/Code/python.homemedia_api/venv/lib/python2.7/site-packages/flask_restplus/swagger.py", line 352, in serialize_operation
    'responses': self.responses_for(doc, method) or None,
  File "/Users/home/Code/python.homemedia_api/venv/lib/python2.7/site-packages/flask_restplus/swagger.py", line 464, in responses_for
    responses[code]['schema'] = self.serialize_schema(model)
  File "/Users/home/Code/python.homemedia_api/venv/lib/python2.7/site-packages/flask_restplus/swagger.py", line 513, in serialize_schema
    self.register_model(model)
  File "/Users/home/Code/python.homemedia_api/venv/lib/python2.7/site-packages/flask_restplus/swagger.py", line 534, in register_model
    raise ValueError('Model {0} not registered'.format(name))
ValueError: Model init_model not registered
2018-11-17 15:32:19,722 - [INFO] werkzeug [_internal, line 88]: 127.0.0.1 - - [17/Nov/2018 15:32:19] "GET /swagger.json HTTP/1.1" 500 -
2018-11-17 15:33:27,769 - [INFO] werkzeug [_internal, line 88]:  * Detected change in '/Users/home/Code/python.homemedia_api/src/api/endpoints/ns_init.py', reloading
2018-11-17 15:33:27,789 - [INFO] werkzeug [_internal, line 88]:  * Restarting with stat
2018-11-17 15:33:28,013 - [INFO] __main__ [app_api, line 46]: ================================================================
2018-11-17 15:33:28,013 - [INFO] __main__ [app_api, line 47]: ================================================================
2018-11-17 15:33:28,013 - [INFO] __main__ [app_api, line 48]: ================================================================
2018-11-17 15:33:28,013 - [INFO] __main__ [app_api, line 49]: Initialising app
2018-11-17 15:33:28,024 - [WARNING] werkzeug [_internal, line 88]:  * Debugger is active!
2018-11-17 15:33:28,038 - [INFO] werkzeug [_internal, line 88]:  * Debugger PIN: 449-218-456
2018-11-17 15:33:30,067 - [INFO] werkzeug [_internal, line 88]:  * Detected change in '/Users/home/Code/python.homemedia_api/src/api/endpoints/ns_init.py', reloading
2018-11-17 15:33:30,120 - [INFO] werkzeug [_internal, line 88]:  * Restarting with stat
2018-11-17 15:33:30,399 - [INFO] __main__ [app_api, line 46]: ================================================================
2018-11-17 15:33:30,399 - [INFO] __main__ [app_api, line 47]: ================================================================
2018-11-17 15:33:30,399 - [INFO] __main__ [app_api, line 48]: ================================================================
2018-11-17 15:33:30,399 - [INFO] __main__ [app_api, line 49]: Initialising app
2018-11-17 15:33:30,409 - [WARNING] werkzeug [_internal, line 88]:  * Debugger is active!
2018-11-17 15:33:30,422 - [INFO] werkzeug [_internal, line 88]:  * Debugger PIN: 449-218-456
2018-11-17 15:33:41,055 - [INFO] __main__ [app_api, line 46]: ================================================================
2018-11-17 15:33:41,055 - [INFO] __main__ [app_api, line 47]: ================================================================
2018-11-17 15:33:41,055 - [INFO] __main__ [app_api, line 48]: ================================================================
2018-11-17 15:33:41,055 - [INFO] __main__ [app_api, line 49]: Initialising app
2018-11-17 15:33:41,065 - [INFO] werkzeug [_internal, line 88]:  * Running on http://127.0.0.1:6500/ (Press CTRL+C to quit)
2018-11-17 15:33:41,066 - [INFO] werkzeug [_internal, line 88]:  * Restarting with stat
2018-11-17 15:33:41,300 - [INFO] __main__ [app_api, line 46]: ================================================================
2018-11-17 15:33:41,300 - [INFO] __main__ [app_api, line 47]: ================================================================
2018-11-17 15:33:41,300 - [INFO] __main__ [app_api, line 48]: ================================================================
2018-11-17 15:33:41,300 - [INFO] __main__ [app_api, line 49]: Initialising app
2018-11-17 15:33:41,311 - [WARNING] werkzeug [_internal, line 88]:  * Debugger is active!
2018-11-17 15:33:41,325 - [INFO] werkzeug [_internal, line 88]:  * Debugger PIN: 449-218-456
2018-11-17 15:33:42,824 - [INFO] werkzeug [_internal, line 88]: 127.0.0.1 - - [17/Nov/2018 15:33:42] "GET / HTTP/1.1" 200 -
2018-11-17 15:33:43,521 - [ERROR] flask_restplus.api [api, line 488]: Unable to render schema
Traceback (most recent call last):
  File "/Users/home/Code/python.homemedia_api/venv/lib/python2.7/site-packages/flask_restplus/api.py", line 483, in __schema__
    self._schema = Swagger(self).as_dict()
  File "/Users/home/Code/python.homemedia_api/venv/lib/python2.7/site-packages/flask_restplus/swagger.py", line 177, in as_dict
    paths[extract_path(url)] = self.serialize_resource(ns, resource, url, kwargs)
  File "/Users/home/Code/python.homemedia_api/venv/lib/python2.7/site-packages/flask_restplus/swagger.py", line 346, in serialize_resource
    path[method] = self.serialize_operation(doc, method)
  File "/Users/home/Code/python.homemedia_api/venv/lib/python2.7/site-packages/flask_restplus/swagger.py", line 352, in serialize_operation
    'responses': self.responses_for(doc, method) or None,
  File "/Users/home/Code/python.homemedia_api/venv/lib/python2.7/site-packages/flask_restplus/swagger.py", line 464, in responses_for
    responses[code]['schema'] = self.serialize_schema(model)
  File "/Users/home/Code/python.homemedia_api/venv/lib/python2.7/site-packages/flask_restplus/swagger.py", line 513, in serialize_schema
    self.register_model(model)
  File "/Users/home/Code/python.homemedia_api/venv/lib/python2.7/site-packages/flask_restplus/swagger.py", line 534, in register_model
    raise ValueError('Model {0} not registered'.format(name))
ValueError: Model init_model not registered
2018-11-17 15:33:43,522 - [INFO] werkzeug [_internal, line 88]: 127.0.0.1 - - [17/Nov/2018 15:33:43] "GET /swagger.json HTTP/1.1" 500 -
2018-11-17 15:35:02,562 - [INFO] werkzeug [_internal, line 88]:  * Detected change in '/Users/home/Code/python.homemedia_api/src/api/endpoints/ns_init.py', reloading
2018-11-17 15:35:02,583 - [INFO] werkzeug [_internal, line 88]:  * Restarting with stat
2018-11-17 15:35:02,839 - [INFO] __main__ [app_api, line 46]: ================================================================
2018-11-17 15:35:02,839 - [INFO] __main__ [app_api, line 47]: ================================================================
2018-11-17 15:35:02,839 - [INFO] __main__ [app_api, line 48]: ================================================================
2018-11-17 15:35:02,839 - [INFO] __main__ [app_api, line 49]: Initialising app
2018-11-17 15:35:02,850 - [WARNING] werkzeug [_internal, line 88]:  * Debugger is active!
2018-11-17 15:35:02,864 - [INFO] werkzeug [_internal, line 88]:  * Debugger PIN: 449-218-456
2018-11-17 15:36:16,813 - [INFO] werkzeug [_internal, line 88]:  * Detected change in '/Users/home/Code/python.homemedia_api/src/api/data_models.py', reloading
2018-11-17 15:36:16,854 - [INFO] werkzeug [_internal, line 88]:  * Restarting with stat
2018-11-17 15:36:35,794 - [INFO] __main__ [app_api, line 46]: ================================================================
2018-11-17 15:36:35,794 - [INFO] __main__ [app_api, line 47]: ================================================================
2018-11-17 15:36:35,794 - [INFO] __main__ [app_api, line 48]: ================================================================
2018-11-17 15:36:35,794 - [INFO] __main__ [app_api, line 49]: Initialising app
2018-11-17 15:36:35,806 - [INFO] werkzeug [_internal, line 88]:  * Running on http://127.0.0.1:6500/ (Press CTRL+C to quit)
2018-11-17 15:36:35,806 - [INFO] werkzeug [_internal, line 88]:  * Restarting with stat
2018-11-17 15:36:36,031 - [INFO] __main__ [app_api, line 46]: ================================================================
2018-11-17 15:36:36,031 - [INFO] __main__ [app_api, line 47]: ================================================================
2018-11-17 15:36:36,031 - [INFO] __main__ [app_api, line 48]: ================================================================
2018-11-17 15:36:36,031 - [INFO] __main__ [app_api, line 49]: Initialising app
2018-11-17 15:36:36,041 - [WARNING] werkzeug [_internal, line 88]:  * Debugger is active!
2018-11-17 15:36:36,056 - [INFO] werkzeug [_internal, line 88]:  * Debugger PIN: 449-218-456
2018-11-17 15:36:37,945 - [INFO] werkzeug [_internal, line 88]: 127.0.0.1 - - [17/Nov/2018 15:36:37] "GET / HTTP/1.1" 200 -
2018-11-17 15:36:38,479 - [INFO] werkzeug [_internal, line 88]: 127.0.0.1 - - [17/Nov/2018 15:36:38] "GET /swagger.json HTTP/1.1" 200 -
2018-11-17 15:36:51,270 - [INFO] werkzeug [_internal, line 88]:  * Detected change in '/Users/home/Code/python.homemedia_api/src/api/data_models.py', reloading
2018-11-17 15:36:51,290 - [INFO] werkzeug [_internal, line 88]:  * Restarting with stat
2018-11-17 15:36:51,523 - [INFO] __main__ [app_api, line 46]: ================================================================
2018-11-17 15:36:51,523 - [INFO] __main__ [app_api, line 47]: ================================================================
2018-11-17 15:36:51,523 - [INFO] __main__ [app_api, line 48]: ================================================================
2018-11-17 15:36:51,523 - [INFO] __main__ [app_api, line 49]: Initialising app
2018-11-17 15:36:51,533 - [WARNING] werkzeug [_internal, line 88]:  * Debugger is active!
2018-11-17 15:36:51,547 - [INFO] werkzeug [_internal, line 88]:  * Debugger PIN: 449-218-456
2018-11-17 15:36:54,597 - [INFO] werkzeug [_internal, line 88]:  * Detected change in '/Users/home/Code/python.homemedia_api/src/api/data_models.py', reloading
2018-11-17 15:36:54,628 - [INFO] werkzeug [_internal, line 88]:  * Restarting with stat
2018-11-17 15:36:55,016 - [INFO] __main__ [app_api, line 46]: ================================================================
2018-11-17 15:36:55,016 - [INFO] __main__ [app_api, line 47]: ================================================================
2018-11-17 15:36:55,016 - [INFO] __main__ [app_api, line 48]: ================================================================
2018-11-17 15:36:55,016 - [INFO] __main__ [app_api, line 49]: Initialising app
2018-11-17 15:36:55,026 - [WARNING] werkzeug [_internal, line 88]:  * Debugger is active!
2018-11-17 15:36:55,041 - [INFO] werkzeug [_internal, line 88]:  * Debugger PIN: 449-218-456
2018-11-17 15:36:58,334 - [INFO] werkzeug [_internal, line 88]: 127.0.0.1 - - [17/Nov/2018 15:36:58] "GET / HTTP/1.1" 200 -
2018-11-17 15:36:58,606 - [INFO] werkzeug [_internal, line 88]: 127.0.0.1 - - [17/Nov/2018 15:36:58] "GET /swagger.json HTTP/1.1" 200 -
2018-11-17 15:36:58,634 - [INFO] werkzeug [_internal, line 88]: 127.0.0.1 - - [17/Nov/2018 15:36:58] "GET /swaggerui/favicon-32x32.png HTTP/1.1" 200 -
2018-11-17 15:36:58,779 - [INFO] werkzeug [_internal, line 88]: 127.0.0.1 - - [17/Nov/2018 15:36:58] "GET /swaggerui/favicon-16x16.png HTTP/1.1" 200 -
2018-11-17 15:37:15,317 - [INFO] werkzeug [_internal, line 88]:  * Detected change in '/Users/home/Code/python.homemedia_api/src/api/endpoints/ns_init.py', reloading
2018-11-17 15:37:15,337 - [INFO] werkzeug [_internal, line 88]:  * Restarting with stat
2018-11-17 15:37:15,594 - [INFO] __main__ [app_api, line 46]: ================================================================
2018-11-17 15:37:15,594 - [INFO] __main__ [app_api, line 47]: ================================================================
2018-11-17 15:37:15,594 - [INFO] __main__ [app_api, line 48]: ================================================================
2018-11-17 15:37:15,594 - [INFO] __main__ [app_api, line 49]: Initialising app
2018-11-17 15:37:15,610 - [WARNING] werkzeug [_internal, line 88]:  * Debugger is active!
2018-11-17 15:37:15,625 - [INFO] werkzeug [_internal, line 88]:  * Debugger PIN: 449-218-456
2018-11-17 15:37:18,080 - [INFO] werkzeug [_internal, line 88]: 127.0.0.1 - - [17/Nov/2018 15:37:18] "GET / HTTP/1.1" 200 -
2018-11-17 15:37:18,349 - [INFO] werkzeug [_internal, line 88]: 127.0.0.1 - - [17/Nov/2018 15:37:18] "GET /swagger.json HTTP/1.1" 200 -
2018-11-17 15:37:18,361 - [INFO] werkzeug [_internal, line 88]: 127.0.0.1 - - [17/Nov/2018 15:37:18] "GET /swaggerui/favicon-32x32.png HTTP/1.1" 200 -
2018-11-17 15:37:44,014 - [INFO] werkzeug [_internal, line 88]:  * Detected change in '/Users/home/Code/python.homemedia_api/src/api/endpoints/ns_init.py', reloading
2018-11-17 15:37:44,033 - [INFO] werkzeug [_internal, line 88]:  * Restarting with stat
2018-11-17 15:37:44,272 - [INFO] __main__ [app_api, line 46]: ================================================================
2018-11-17 15:37:44,272 - [INFO] __main__ [app_api, line 47]: ================================================================
2018-11-17 15:37:44,272 - [INFO] __main__ [app_api, line 48]: ================================================================
2018-11-17 15:37:44,272 - [INFO] __main__ [app_api, line 49]: Initialising app
2018-11-17 15:37:44,282 - [WARNING] werkzeug [_internal, line 88]:  * Debugger is active!
2018-11-17 15:37:44,301 - [INFO] werkzeug [_internal, line 88]:  * Debugger PIN: 449-218-456
2018-11-17 15:37:46,650 - [INFO] werkzeug [_internal, line 88]: 127.0.0.1 - - [17/Nov/2018 15:37:46] "GET / HTTP/1.1" 200 -
2018-11-17 15:37:46,926 - [ERROR] flask_restplus.api [api, line 488]: Unable to render schema
Traceback (most recent call last):
  File "/Users/home/Code/python.homemedia_api/venv/lib/python2.7/site-packages/flask_restplus/api.py", line 483, in __schema__
    self._schema = Swagger(self).as_dict()
  File "/Users/home/Code/python.homemedia_api/venv/lib/python2.7/site-packages/flask_restplus/swagger.py", line 177, in as_dict
    paths[extract_path(url)] = self.serialize_resource(ns, resource, url, kwargs)
  File "/Users/home/Code/python.homemedia_api/venv/lib/python2.7/site-packages/flask_restplus/swagger.py", line 346, in serialize_resource
    path[method] = self.serialize_operation(doc, method)
  File "/Users/home/Code/python.homemedia_api/venv/lib/python2.7/site-packages/flask_restplus/swagger.py", line 352, in serialize_operation
    'responses': self.responses_for(doc, method) or None,
  File "/Users/home/Code/python.homemedia_api/venv/lib/python2.7/site-packages/flask_restplus/swagger.py", line 464, in responses_for
    responses[code]['schema'] = self.serialize_schema(model)
  File "/Users/home/Code/python.homemedia_api/venv/lib/python2.7/site-packages/flask_restplus/swagger.py", line 513, in serialize_schema
    self.register_model(model)
  File "/Users/home/Code/python.homemedia_api/venv/lib/python2.7/site-packages/flask_restplus/swagger.py", line 534, in register_model
    raise ValueError('Model {0} not registered'.format(name))
ValueError: Model init_model not registered
2018-11-17 15:37:46,931 - [INFO] werkzeug [_internal, line 88]: 127.0.0.1 - - [17/Nov/2018 15:37:46] "GET /swagger.json HTTP/1.1" 500 -
2018-11-17 15:37:46,957 - [INFO] werkzeug [_internal, line 88]: 127.0.0.1 - - [17/Nov/2018 15:37:46] "GET /swaggerui/favicon-32x32.png HTTP/1.1" 200 -
2018-11-17 15:39:43,937 - [INFO] werkzeug [_internal, line 88]:  * Detected change in '/Users/home/Code/python.homemedia_api/src/api/data_models.py', reloading
2018-11-17 15:39:43,980 - [INFO] werkzeug [_internal, line 88]:  * Restarting with stat
2018-11-17 15:39:44,245 - [INFO] __main__ [app_api, line 46]: ================================================================
2018-11-17 15:39:44,246 - [INFO] __main__ [app_api, line 47]: ================================================================
2018-11-17 15:39:44,246 - [INFO] __main__ [app_api, line 48]: ================================================================
2018-11-17 15:39:44,246 - [INFO] __main__ [app_api, line 49]: Initialising app
2018-11-17 15:39:44,258 - [WARNING] werkzeug [_internal, line 88]:  * Debugger is active!
2018-11-17 15:39:44,279 - [INFO] werkzeug [_internal, line 88]:  * Debugger PIN: 449-218-456
2018-11-17 15:39:48,145 - [INFO] werkzeug [_internal, line 88]: 127.0.0.1 - - [17/Nov/2018 15:39:48] "GET / HTTP/1.1" 200 -
2018-11-17 15:39:48,330 - [INFO] werkzeug [_internal, line 88]: 127.0.0.1 - - [17/Nov/2018 15:39:48] "GET /swaggerui/favicon-32x32.png HTTP/1.1" 200 -
2018-11-17 15:39:48,328 - [INFO] werkzeug [_internal, line 88]: 127.0.0.1 - - [17/Nov/2018 15:39:48] "GET /swagger.json HTTP/1.1" 200 -
2018-11-17 15:39:59,562 - [INFO] werkzeug [_internal, line 88]:  * Detected change in '/Users/home/Code/python.homemedia_api/src/api/data_models.py', reloading
2018-11-17 15:39:59,582 - [INFO] werkzeug [_internal, line 88]:  * Restarting with stat
2018-11-17 15:39:59,829 - [INFO] __main__ [app_api, line 46]: ================================================================
2018-11-17 15:39:59,829 - [INFO] __main__ [app_api, line 47]: ================================================================
2018-11-17 15:39:59,829 - [INFO] __main__ [app_api, line 48]: ================================================================
2018-11-17 15:39:59,829 - [INFO] __main__ [app_api, line 49]: Initialising app
2018-11-17 15:39:59,839 - [WARNING] werkzeug [_internal, line 88]:  * Debugger is active!
2018-11-17 15:39:59,853 - [INFO] werkzeug [_internal, line 88]:  * Debugger PIN: 449-218-456
2018-11-17 15:40:01,255 - [INFO] werkzeug [_internal, line 88]: 127.0.0.1 - - [17/Nov/2018 15:40:01] "GET / HTTP/1.1" 200 -
2018-11-17 15:40:01,735 - [ERROR] flask_restplus.api [api, line 488]: Unable to render schema
Traceback (most recent call last):
  File "/Users/home/Code/python.homemedia_api/venv/lib/python2.7/site-packages/flask_restplus/api.py", line 483, in __schema__
    self._schema = Swagger(self).as_dict()
  File "/Users/home/Code/python.homemedia_api/venv/lib/python2.7/site-packages/flask_restplus/swagger.py", line 177, in as_dict
    paths[extract_path(url)] = self.serialize_resource(ns, resource, url, kwargs)
  File "/Users/home/Code/python.homemedia_api/venv/lib/python2.7/site-packages/flask_restplus/swagger.py", line 346, in serialize_resource
    path[method] = self.serialize_operation(doc, method)
  File "/Users/home/Code/python.homemedia_api/venv/lib/python2.7/site-packages/flask_restplus/swagger.py", line 352, in serialize_operation
    'responses': self.responses_for(doc, method) or None,
  File "/Users/home/Code/python.homemedia_api/venv/lib/python2.7/site-packages/flask_restplus/swagger.py", line 464, in responses_for
    responses[code]['schema'] = self.serialize_schema(model)
  File "/Users/home/Code/python.homemedia_api/venv/lib/python2.7/site-packages/flask_restplus/swagger.py", line 513, in serialize_schema
    self.register_model(model)
  File "/Users/home/Code/python.homemedia_api/venv/lib/python2.7/site-packages/flask_restplus/swagger.py", line 534, in register_model
    raise ValueError('Model {0} not registered'.format(name))
ValueError: Model init_model not registered
2018-11-17 15:40:01,741 - [INFO] werkzeug [_internal, line 88]: 127.0.0.1 - - [17/Nov/2018 15:40:01] "GET /swagger.json HTTP/1.1" 500 -
2018-11-17 15:40:01,751 - [INFO] werkzeug [_internal, line 88]: 127.0.0.1 - - [17/Nov/2018 15:40:01] "GET /swaggerui/favicon-32x32.png HTTP/1.1" 200 -
2018-11-17 15:40:16,103 - [INFO] werkzeug [_internal, line 88]:  * Detected change in '/Users/home/Code/python.homemedia_api/src/api/data_models.py', reloading
2018-11-17 15:40:16,145 - [INFO] werkzeug [_internal, line 88]:  * Restarting with stat
2018-11-17 15:40:16,513 - [INFO] __main__ [app_api, line 46]: ================================================================
2018-11-17 15:40:16,513 - [INFO] __main__ [app_api, line 47]: ================================================================
2018-11-17 15:40:16,513 - [INFO] __main__ [app_api, line 48]: ================================================================
2018-11-17 15:40:16,513 - [INFO] __main__ [app_api, line 49]: Initialising app
2018-11-17 15:40:16,523 - [WARNING] werkzeug [_internal, line 88]:  * Debugger is active!
2018-11-17 15:40:16,536 - [INFO] werkzeug [_internal, line 88]:  * Debugger PIN: 449-218-456
2018-11-17 15:40:30,361 - [INFO] werkzeug [_internal, line 88]: 127.0.0.1 - - [17/Nov/2018 15:40:30] "GET / HTTP/1.1" 200 -
2018-11-17 15:40:30,643 - [INFO] werkzeug [_internal, line 88]: 127.0.0.1 - - [17/Nov/2018 15:40:30] "GET /swagger.json HTTP/1.1" 200 -
2018-11-17 15:40:30,652 - [INFO] werkzeug [_internal, line 88]: 127.0.0.1 - - [17/Nov/2018 15:40:30] "GET /swaggerui/favicon-32x32.png HTTP/1.1" 200 -
2018-11-17 15:41:40,760 - [INFO] werkzeug [_internal, line 88]:  * Detected change in '/Users/home/Code/python.homemedia_api/src/app_api.py', reloading
2018-11-17 15:41:40,780 - [INFO] werkzeug [_internal, line 88]:  * Restarting with stat
2018-11-17 15:41:41,051 - [INFO] __main__ [app_api, line 42]: ================================================================
2018-11-17 15:41:41,051 - [INFO] __main__ [app_api, line 43]: ================================================================
2018-11-17 15:41:41,051 - [INFO] __main__ [app_api, line 44]: ================================================================
2018-11-17 15:41:41,051 - [INFO] __main__ [app_api, line 45]: Initialising app
2018-11-17 15:41:41,060 - [WARNING] werkzeug [_internal, line 88]:  * Debugger is active!
2018-11-17 15:41:41,074 - [INFO] werkzeug [_internal, line 88]:  * Debugger PIN: 449-218-456
2018-11-17 15:41:47,136 - [INFO] __main__ [app_api, line 42]: ================================================================
2018-11-17 15:41:47,136 - [INFO] __main__ [app_api, line 43]: ================================================================
2018-11-17 15:41:47,136 - [INFO] __main__ [app_api, line 44]: ================================================================
2018-11-17 15:41:47,137 - [INFO] __main__ [app_api, line 45]: Initialising app
2018-11-17 15:41:47,155 - [INFO] werkzeug [_internal, line 88]:  * Running on http://127.0.0.1:6500/ (Press CTRL+C to quit)
2018-11-17 15:41:47,156 - [INFO] werkzeug [_internal, line 88]:  * Restarting with stat
2018-11-17 15:41:47,442 - [INFO] __main__ [app_api, line 42]: ================================================================
2018-11-17 15:41:47,443 - [INFO] __main__ [app_api, line 43]: ================================================================
2018-11-17 15:41:47,443 - [INFO] __main__ [app_api, line 44]: ================================================================
2018-11-17 15:41:47,443 - [INFO] __main__ [app_api, line 45]: Initialising app
2018-11-17 15:41:47,452 - [WARNING] werkzeug [_internal, line 88]:  * Debugger is active!
2018-11-17 15:41:47,475 - [INFO] werkzeug [_internal, line 88]:  * Debugger PIN: 449-218-456
2018-11-17 15:41:50,056 - [INFO] werkzeug [_internal, line 88]: 127.0.0.1 - - [17/Nov/2018 15:41:50] "GET / HTTP/1.1" 200 -
2018-11-17 15:41:50,474 - [ERROR] flask_restplus.api [api, line 488]: Unable to render schema
Traceback (most recent call last):
  File "/Users/home/Code/python.homemedia_api/venv/lib/python2.7/site-packages/flask_restplus/api.py", line 483, in __schema__
    self._schema = Swagger(self).as_dict()
  File "/Users/home/Code/python.homemedia_api/venv/lib/python2.7/site-packages/flask_restplus/swagger.py", line 177, in as_dict
    paths[extract_path(url)] = self.serialize_resource(ns, resource, url, kwargs)
  File "/Users/home/Code/python.homemedia_api/venv/lib/python2.7/site-packages/flask_restplus/swagger.py", line 346, in serialize_resource
    path[method] = self.serialize_operation(doc, method)
  File "/Users/home/Code/python.homemedia_api/venv/lib/python2.7/site-packages/flask_restplus/swagger.py", line 352, in serialize_operation
    'responses': self.responses_for(doc, method) or None,
  File "/Users/home/Code/python.homemedia_api/venv/lib/python2.7/site-packages/flask_restplus/swagger.py", line 464, in responses_for
    responses[code]['schema'] = self.serialize_schema(model)
  File "/Users/home/Code/python.homemedia_api/venv/lib/python2.7/site-packages/flask_restplus/swagger.py", line 513, in serialize_schema
    self.register_model(model)
  File "/Users/home/Code/python.homemedia_api/venv/lib/python2.7/site-packages/flask_restplus/swagger.py", line 534, in register_model
    raise ValueError('Model {0} not registered'.format(name))
ValueError: Model folder_model not registered
2018-11-17 15:41:50,476 - [INFO] werkzeug [_internal, line 88]: 127.0.0.1 - - [17/Nov/2018 15:41:50] "GET /swagger.json HTTP/1.1" 500 -
2018-11-17 15:41:50,507 - [INFO] werkzeug [_internal, line 88]: 127.0.0.1 - - [17/Nov/2018 15:41:50] "GET /swaggerui/favicon-32x32.png HTTP/1.1" 200 -
2018-11-17 15:42:55,437 - [INFO] werkzeug [_internal, line 88]:  * Detected change in '/Users/home/Code/python.homemedia_api/src/app_api.py', reloading
2018-11-17 15:42:55,456 - [INFO] werkzeug [_internal, line 88]:  * Restarting with stat
2018-11-17 15:42:55,945 - [INFO] __main__ [app_api, line 43]: ================================================================
2018-11-17 15:42:55,953 - [INFO] __main__ [app_api, line 44]: ================================================================
2018-11-17 15:42:55,954 - [INFO] __main__ [app_api, line 45]: ================================================================
2018-11-17 15:42:55,954 - [INFO] __main__ [app_api, line 46]: Initialising app
2018-11-17 15:42:55,972 - [WARNING] werkzeug [_internal, line 88]:  * Debugger is active!
2018-11-17 15:42:55,986 - [INFO] werkzeug [_internal, line 88]:  * Debugger PIN: 449-218-456
2018-11-17 15:43:48,706 - [INFO] werkzeug [_internal, line 88]:  * Detected change in '/Users/home/Code/python.homemedia_api/venv/lib/python2.7/site-packages/flask_restplus/representations.py', reloading
2018-11-17 15:43:48,756 - [INFO] werkzeug [_internal, line 88]:  * Restarting with stat
2018-11-17 15:43:49,328 - [INFO] __main__ [app_api, line 43]: ================================================================
2018-11-17 15:43:49,329 - [INFO] __main__ [app_api, line 44]: ================================================================
2018-11-17 15:43:49,329 - [INFO] __main__ [app_api, line 45]: ================================================================
2018-11-17 15:43:49,330 - [INFO] __main__ [app_api, line 46]: Initialising app
2018-11-17 15:43:49,378 - [WARNING] werkzeug [_internal, line 88]:  * Debugger is active!
2018-11-17 15:43:49,425 - [INFO] werkzeug [_internal, line 88]:  * Debugger PIN: 449-218-456
2018-11-17 15:44:01,737 - [INFO] __main__ [app_api, line 43]: ================================================================
2018-11-17 15:44:01,738 - [INFO] __main__ [app_api, line 44]: ================================================================
2018-11-17 15:44:01,738 - [INFO] __main__ [app_api, line 45]: ================================================================
2018-11-17 15:44:01,738 - [INFO] __main__ [app_api, line 46]: Initialising app
2018-11-17 15:44:01,748 - [INFO] werkzeug [_internal, line 88]:  * Running on http://127.0.0.1:6500/ (Press CTRL+C to quit)
2018-11-17 15:44:01,749 - [INFO] werkzeug [_internal, line 88]:  * Restarting with stat
2018-11-17 15:44:02,016 - [INFO] __main__ [app_api, line 43]: ================================================================
2018-11-17 15:44:02,016 - [INFO] __main__ [app_api, line 44]: ================================================================
2018-11-17 15:44:02,017 - [INFO] __main__ [app_api, line 45]: ================================================================
2018-11-17 15:44:02,017 - [INFO] __main__ [app_api, line 46]: Initialising app
2018-11-17 15:44:02,031 - [WARNING] werkzeug [_internal, line 88]:  * Debugger is active!
2018-11-17 15:44:02,048 - [INFO] werkzeug [_internal, line 88]:  * Debugger PIN: 449-218-456
2018-11-17 15:44:03,868 - [INFO] werkzeug [_internal, line 88]: 127.0.0.1 - - [17/Nov/2018 15:44:03] "GET / HTTP/1.1" 200 -
2018-11-17 15:44:03,944 - [INFO] werkzeug [_internal, line 88]: 127.0.0.1 - - [17/Nov/2018 15:44:03] "GET /swaggerui/bower/swagger-ui/dist/css/reset.css HTTP/1.1" 200 -
2018-11-17 15:44:03,954 - [INFO] werkzeug [_internal, line 88]: 127.0.0.1 - - [17/Nov/2018 15:44:03] "GET /swaggerui/bower/swagger-ui/dist/lib/jquery.wiggle.min.js HTTP/1.1" 200 -
2018-11-17 15:44:03,966 - [INFO] werkzeug [_internal, line 88]: 127.0.0.1 - - [17/Nov/2018 15:44:03] "GET /swaggerui/bower/swagger-ui/dist/lib/jquery.ba-bbq.min.js HTTP/1.1" 200 -
2018-11-17 15:44:03,979 - [INFO] werkzeug [_internal, line 88]: 127.0.0.1 - - [17/Nov/2018 15:44:03] "GET /swaggerui/bower/swagger-ui/dist/lib/handlebars-4.0.5.js HTTP/1.1" 200 -
2018-11-17 15:44:04,006 - [INFO] werkzeug [_internal, line 88]: 127.0.0.1 - - [17/Nov/2018 15:44:04] "GET /swaggerui/bower/swagger-ui/dist/lib/lodash.min.js HTTP/1.1" 200 -
2018-11-17 15:44:04,018 - [INFO] werkzeug [_internal, line 88]: 127.0.0.1 - - [17/Nov/2018 15:44:04] "GET /swaggerui/bower/swagger-ui/dist/lib/backbone-min.js HTTP/1.1" 200 -
2018-11-17 15:44:04,029 - [INFO] werkzeug [_internal, line 88]: 127.0.0.1 - - [17/Nov/2018 15:44:04] "GET /swaggerui/bower/swagger-ui/dist/swagger-ui.js HTTP/1.1" 200 -
2018-11-17 15:44:04,057 - [INFO] werkzeug [_internal, line 88]: 127.0.0.1 - - [17/Nov/2018 15:44:04] "GET /swaggerui/bower/swagger-ui/dist/css/typography.css HTTP/1.1" 200 -
2018-11-17 15:44:04,060 - [INFO] werkzeug [_internal, line 88]: 127.0.0.1 - - [17/Nov/2018 15:44:04] "GET /swaggerui/bower/swagger-ui/dist/css/screen.css HTTP/1.1" 200 -
2018-11-17 15:44:04,070 - [INFO] werkzeug [_internal, line 88]: 127.0.0.1 - - [17/Nov/2018 15:44:04] "GET /swaggerui/bower/swagger-ui/dist/lib/highlight.9.1.0.pack.js HTTP/1.1" 200 -
2018-11-17 15:44:04,085 - [INFO] werkzeug [_internal, line 88]: 127.0.0.1 - - [17/Nov/2018 15:44:04] "GET /swaggerui/bower/swagger-ui/dist/lib/highlight.9.1.0.pack_extended.js HTTP/1.1" 200 -
2018-11-17 15:44:04,085 - [INFO] werkzeug [_internal, line 88]: 127.0.0.1 - - [17/Nov/2018 15:44:04] "GET /swaggerui/bower/swagger-ui/dist/lib/jquery.slideto.min.js HTTP/1.1" 200 -
2018-11-17 15:44:04,094 - [INFO] werkzeug [_internal, line 88]: 127.0.0.1 - - [17/Nov/2018 15:44:04] "GET /swaggerui/bower/swagger-ui/dist/lib/jquery-1.8.0.min.js HTTP/1.1" 200 -
2018-11-17 15:44:04,098 - [INFO] werkzeug [_internal, line 88]: 127.0.0.1 - - [17/Nov/2018 15:44:04] "GET /swaggerui/bower/swagger-ui/dist/lib/jsoneditor.min.js HTTP/1.1" 200 -
2018-11-17 15:44:04,101 - [INFO] werkzeug [_internal, line 88]: 127.0.0.1 - - [17/Nov/2018 15:44:04] "GET /swaggerui/bower/swagger-ui/dist/lib/marked.js HTTP/1.1" 200 -
2018-11-17 15:44:04,109 - [INFO] werkzeug [_internal, line 88]: 127.0.0.1 - - [17/Nov/2018 15:44:04] "GET /swaggerui/bower/swagger-ui/dist/lib/swagger-oauth.js HTTP/1.1" 200 -
2018-11-17 15:44:04,120 - [INFO] werkzeug [_internal, line 88]: 127.0.0.1 - - [17/Nov/2018 15:44:04] "GET /swaggerui/bower/swagger-ui/dist/lib/object-assign-pollyfill.js HTTP/1.1" 200 -
2018-11-17 15:44:04,482 - [INFO] werkzeug [_internal, line 88]: 127.0.0.1 - - [17/Nov/2018 15:44:04] "GET /swaggerui/bower/swagger-ui/dist/fonts/DroidSans.ttf HTTP/1.1" 200 -
2018-11-17 15:44:04,573 - [ERROR] api.restplus [restplus, line 20]: Model folder_model not registered
Traceback (most recent call last):
  File "/Users/home/Code/python.homemedia_api/venv/lib/python2.7/site-packages/flask/app.py", line 1813, in full_dispatch_request
    rv = self.dispatch_request()
  File "/Users/home/Code/python.homemedia_api/venv/lib/python2.7/site-packages/flask/app.py", line 1799, in dispatch_request
    return self.view_functions[rule.endpoint](**req.view_args)
  File "/Users/home/Code/python.homemedia_api/venv/lib/python2.7/site-packages/flask_restplus/api.py", line 313, in wrapper
    resp = resource(*args, **kwargs)
  File "/Users/home/Code/python.homemedia_api/venv/lib/python2.7/site-packages/flask/views.py", line 88, in view
    return self.dispatch_request(*args, **kwargs)
  File "/Users/home/Code/python.homemedia_api/venv/lib/python2.7/site-packages/flask_restplus/resource.py", line 44, in dispatch_request
    resp = meth(*args, **kwargs)
  File "/Users/home/Code/python.homemedia_api/venv/lib/python2.7/site-packages/flask_restplus/api.py", line 771, in get
    return self.api.__schema__
  File "/Users/home/Code/python.homemedia_api/venv/lib/python2.7/site-packages/werkzeug/utils.py", line 73, in __get__
    value = self.func(obj)
  File "/Users/home/Code/python.homemedia_api/venv/lib/python2.7/site-packages/flask_restplus/api.py", line 472, in __schema__
    self._schema = Swagger(self).as_dict()
  File "/Users/home/Code/python.homemedia_api/venv/lib/python2.7/site-packages/flask_restplus/swagger.py", line 167, in as_dict
    paths[extract_path(url)] = self.serialize_resource(ns, resource, url, kwargs)
  File "/Users/home/Code/python.homemedia_api/venv/lib/python2.7/site-packages/flask_restplus/swagger.py", line 306, in serialize_resource
    path[method] = self.serialize_operation(doc, method)
  File "/Users/home/Code/python.homemedia_api/venv/lib/python2.7/site-packages/flask_restplus/swagger.py", line 312, in serialize_operation
    'responses': self.responses_for(doc, method) or None,
  File "/Users/home/Code/python.homemedia_api/venv/lib/python2.7/site-packages/flask_restplus/swagger.py", line 397, in responses_for
    responses[code]['schema'] = self.serialize_schema(model)
  File "/Users/home/Code/python.homemedia_api/venv/lib/python2.7/site-packages/flask_restplus/swagger.py", line 432, in serialize_schema
    self.register_model(model)
  File "/Users/home/Code/python.homemedia_api/venv/lib/python2.7/site-packages/flask_restplus/swagger.py", line 453, in register_model
    raise ValueError('Model {0} not registered'.format(name))
ValueError: Model folder_model not registered
2018-11-17 15:44:04,575 - [ERROR] api.restplus [restplus, line 20]: 
Traceback (most recent call last):
  File "/Users/home/Code/python.homemedia_api/venv/lib/python2.7/site-packages/flask/app.py", line 2292, in wsgi_app
    response = self.full_dispatch_request()
  File "/Users/home/Code/python.homemedia_api/venv/lib/python2.7/site-packages/flask/app.py", line 1815, in full_dispatch_request
    rv = self.handle_user_exception(e)
  File "/Users/home/Code/python.homemedia_api/venv/lib/python2.7/site-packages/flask_restplus/api.py", line 557, in error_router
    return original_handler(e)
  File "/Users/home/Code/python.homemedia_api/venv/lib/python2.7/site-packages/flask_cors/extension.py", line 161, in wrapped_function
    return cors_after_request(app.make_response(f(*args, **kwargs)))
  File "/Users/home/Code/python.homemedia_api/venv/lib/python2.7/site-packages/flask/app.py", line 1695, in handle_user_exception
    assert exc_value is e
AssertionError
2018-11-17 15:44:04,582 - [INFO] werkzeug [_internal, line 88]: 127.0.0.1 - - [17/Nov/2018 15:44:04] "GET /swagger.json HTTP/1.1" 500 -
2018-11-17 15:44:29,464 - [INFO] werkzeug [_internal, line 88]:  * Detected change in '/Users/home/Code/python.homemedia_api/venv/lib/python2.7/site-packages/flask_restplus/representations.py', reloading
2018-11-17 15:44:29,506 - [INFO] werkzeug [_internal, line 88]:  * Restarting with stat
2018-11-17 15:44:30,015 - [INFO] __main__ [app_api, line 43]: ================================================================
2018-11-17 15:44:30,017 - [INFO] __main__ [app_api, line 44]: ================================================================
2018-11-17 15:44:30,017 - [INFO] __main__ [app_api, line 45]: ================================================================
2018-11-17 15:44:30,017 - [INFO] __main__ [app_api, line 46]: Initialising app
2018-11-17 15:44:30,049 - [WARNING] werkzeug [_internal, line 88]:  * Debugger is active!
2018-11-17 15:44:30,069 - [INFO] werkzeug [_internal, line 88]:  * Debugger PIN: 449-218-456
2018-11-17 15:44:35,964 - [INFO] __main__ [app_api, line 43]: ================================================================
2018-11-17 15:44:35,965 - [INFO] __main__ [app_api, line 44]: ================================================================
2018-11-17 15:44:35,965 - [INFO] __main__ [app_api, line 45]: ================================================================
2018-11-17 15:44:35,965 - [INFO] __main__ [app_api, line 46]: Initialising app
2018-11-17 15:44:35,974 - [INFO] werkzeug [_internal, line 88]:  * Running on http://127.0.0.1:6500/ (Press CTRL+C to quit)
2018-11-17 15:44:35,975 - [INFO] werkzeug [_internal, line 88]:  * Restarting with stat
2018-11-17 15:44:36,188 - [INFO] __main__ [app_api, line 43]: ================================================================
2018-11-17 15:44:36,188 - [INFO] __main__ [app_api, line 44]: ================================================================
2018-11-17 15:44:36,188 - [INFO] __main__ [app_api, line 45]: ================================================================
2018-11-17 15:44:36,188 - [INFO] __main__ [app_api, line 46]: Initialising app
2018-11-17 15:44:36,214 - [WARNING] werkzeug [_internal, line 88]:  * Debugger is active!
2018-11-17 15:44:36,231 - [INFO] werkzeug [_internal, line 88]:  * Debugger PIN: 449-218-456
2018-11-17 15:44:39,284 - [INFO] werkzeug [_internal, line 88]: 127.0.0.1 - - [17/Nov/2018 15:44:39] "GET / HTTP/1.1" 200 -
2018-11-17 15:44:39,692 - [ERROR] flask_restplus.api [api, line 482]: Unable to render schema
Traceback (most recent call last):
  File "/Users/home/Code/python.homemedia_api/venv/lib/python2.7/site-packages/flask_restplus/api.py", line 477, in __schema__
    self._schema = Swagger(self).as_dict()
  File "/Users/home/Code/python.homemedia_api/venv/lib/python2.7/site-packages/flask_restplus/swagger.py", line 177, in as_dict
    paths[extract_path(url)] = self.serialize_resource(ns, resource, url, kwargs)
  File "/Users/home/Code/python.homemedia_api/venv/lib/python2.7/site-packages/flask_restplus/swagger.py", line 319, in serialize_resource
    path[method] = self.serialize_operation(doc, method)
  File "/Users/home/Code/python.homemedia_api/venv/lib/python2.7/site-packages/flask_restplus/swagger.py", line 325, in serialize_operation
    'responses': self.responses_for(doc, method) or None,
  File "/Users/home/Code/python.homemedia_api/venv/lib/python2.7/site-packages/flask_restplus/swagger.py", line 435, in responses_for
    responses[code]['schema'] = self.serialize_schema(model)
  File "/Users/home/Code/python.homemedia_api/venv/lib/python2.7/site-packages/flask_restplus/swagger.py", line 484, in serialize_schema
    self.register_model(model)
  File "/Users/home/Code/python.homemedia_api/venv/lib/python2.7/site-packages/flask_restplus/swagger.py", line 505, in register_model
    raise ValueError('Model {0} not registered'.format(name))
ValueError: Model folder_model not registered
2018-11-17 15:44:39,694 - [INFO] werkzeug [_internal, line 88]: 127.0.0.1 - - [17/Nov/2018 15:44:39] "GET /swagger.json HTTP/1.1" 500 -
2018-11-17 15:44:39,754 - [INFO] werkzeug [_internal, line 88]: 127.0.0.1 - - [17/Nov/2018 15:44:39] "GET /swaggerui/favicon-32x32.png HTTP/1.1" 200 -
2018-11-17 15:45:35,096 - [INFO] werkzeug [_internal, line 88]:  * Detected change in '/Users/home/Code/python.homemedia_api/src/api/data_models.py', reloading
2018-11-17 15:45:35,116 - [INFO] werkzeug [_internal, line 88]:  * Restarting with stat
2018-11-17 15:45:35,356 - [INFO] __main__ [app_api, line 43]: ================================================================
2018-11-17 15:45:35,356 - [INFO] __main__ [app_api, line 44]: ================================================================
2018-11-17 15:45:35,356 - [INFO] __main__ [app_api, line 45]: ================================================================
2018-11-17 15:45:35,356 - [INFO] __main__ [app_api, line 46]: Initialising app
2018-11-17 15:45:35,365 - [WARNING] werkzeug [_internal, line 88]:  * Debugger is active!
2018-11-17 15:45:35,381 - [INFO] werkzeug [_internal, line 88]:  * Debugger PIN: 449-218-456
2018-11-17 15:45:37,129 - [INFO] __main__ [app_api, line 43]: ================================================================
2018-11-17 15:45:37,129 - [INFO] __main__ [app_api, line 44]: ================================================================
2018-11-17 15:45:37,129 - [INFO] __main__ [app_api, line 45]: ================================================================
2018-11-17 15:45:37,129 - [INFO] __main__ [app_api, line 46]: Initialising app
2018-11-17 15:45:37,139 - [INFO] werkzeug [_internal, line 88]:  * Running on http://127.0.0.1:6500/ (Press CTRL+C to quit)
2018-11-17 15:45:37,140 - [INFO] werkzeug [_internal, line 88]:  * Restarting with stat
2018-11-17 15:45:37,434 - [INFO] __main__ [app_api, line 43]: ================================================================
2018-11-17 15:45:37,434 - [INFO] __main__ [app_api, line 44]: ================================================================
2018-11-17 15:45:37,435 - [INFO] __main__ [app_api, line 45]: ================================================================
2018-11-17 15:45:37,435 - [INFO] __main__ [app_api, line 46]: Initialising app
2018-11-17 15:45:37,451 - [WARNING] werkzeug [_internal, line 88]:  * Debugger is active!
2018-11-17 15:45:37,464 - [INFO] werkzeug [_internal, line 88]:  * Debugger PIN: 449-218-456
2018-11-17 15:45:38,981 - [INFO] werkzeug [_internal, line 88]: 127.0.0.1 - - [17/Nov/2018 15:45:38] "GET / HTTP/1.1" 200 -
2018-11-17 15:45:39,489 - [ERROR] flask_restplus.api [api, line 482]: Unable to render schema
Traceback (most recent call last):
  File "/Users/home/Code/python.homemedia_api/venv/lib/python2.7/site-packages/flask_restplus/api.py", line 477, in __schema__
    self._schema = Swagger(self).as_dict()
  File "/Users/home/Code/python.homemedia_api/venv/lib/python2.7/site-packages/flask_restplus/swagger.py", line 177, in as_dict
    paths[extract_path(url)] = self.serialize_resource(ns, resource, url, kwargs)
  File "/Users/home/Code/python.homemedia_api/venv/lib/python2.7/site-packages/flask_restplus/swagger.py", line 319, in serialize_resource
    path[method] = self.serialize_operation(doc, method)
  File "/Users/home/Code/python.homemedia_api/venv/lib/python2.7/site-packages/flask_restplus/swagger.py", line 325, in serialize_operation
    'responses': self.responses_for(doc, method) or None,
  File "/Users/home/Code/python.homemedia_api/venv/lib/python2.7/site-packages/flask_restplus/swagger.py", line 435, in responses_for
    responses[code]['schema'] = self.serialize_schema(model)
  File "/Users/home/Code/python.homemedia_api/venv/lib/python2.7/site-packages/flask_restplus/swagger.py", line 484, in serialize_schema
    self.register_model(model)
  File "/Users/home/Code/python.homemedia_api/venv/lib/python2.7/site-packages/flask_restplus/swagger.py", line 505, in register_model
    raise ValueError('Model {0} not registered'.format(name))
ValueError: Model folder_model not registered
2018-11-17 15:45:39,490 - [INFO] werkzeug [_internal, line 88]: 127.0.0.1 - - [17/Nov/2018 15:45:39] "GET /swagger.json HTTP/1.1" 500 -
2018-11-17 15:45:51,655 - [INFO] werkzeug [_internal, line 88]:  * Detected change in '/Users/home/Code/python.homemedia_api/src/api/data_models.py', reloading
2018-11-17 15:45:51,686 - [INFO] werkzeug [_internal, line 88]:  * Restarting with stat
2018-11-17 15:45:52,128 - [INFO] __main__ [app_api, line 43]: ================================================================
2018-11-17 15:45:52,129 - [INFO] __main__ [app_api, line 44]: ================================================================
2018-11-17 15:45:52,129 - [INFO] __main__ [app_api, line 45]: ================================================================
2018-11-17 15:45:52,129 - [INFO] __main__ [app_api, line 46]: Initialising app
2018-11-17 15:45:52,143 - [WARNING] werkzeug [_internal, line 88]:  * Debugger is active!
2018-11-17 15:45:52,175 - [INFO] werkzeug [_internal, line 88]:  * Debugger PIN: 449-218-456
2018-11-17 15:45:53,166 - [INFO] __main__ [app_api, line 43]: ================================================================
2018-11-17 15:45:53,166 - [INFO] __main__ [app_api, line 44]: ================================================================
2018-11-17 15:45:53,167 - [INFO] __main__ [app_api, line 45]: ================================================================
2018-11-17 15:45:53,167 - [INFO] __main__ [app_api, line 46]: Initialising app
2018-11-17 15:45:53,179 - [INFO] werkzeug [_internal, line 88]:  * Running on http://127.0.0.1:6500/ (Press CTRL+C to quit)
2018-11-17 15:45:53,181 - [INFO] werkzeug [_internal, line 88]:  * Restarting with stat
2018-11-17 15:45:53,435 - [INFO] __main__ [app_api, line 43]: ================================================================
2018-11-17 15:45:53,436 - [INFO] __main__ [app_api, line 44]: ================================================================
2018-11-17 15:45:53,436 - [INFO] __main__ [app_api, line 45]: ================================================================
2018-11-17 15:45:53,436 - [INFO] __main__ [app_api, line 46]: Initialising app
2018-11-17 15:45:53,445 - [WARNING] werkzeug [_internal, line 88]:  * Debugger is active!
2018-11-17 15:45:53,459 - [INFO] werkzeug [_internal, line 88]:  * Debugger PIN: 449-218-456
2018-11-17 15:45:54,773 - [INFO] werkzeug [_internal, line 88]: 127.0.0.1 - - [17/Nov/2018 15:45:54] "GET / HTTP/1.1" 200 -
2018-11-17 15:45:55,291 - [ERROR] flask_restplus.api [api, line 482]: Unable to render schema
Traceback (most recent call last):
  File "/Users/home/Code/python.homemedia_api/venv/lib/python2.7/site-packages/flask_restplus/api.py", line 477, in __schema__
    self._schema = Swagger(self).as_dict()
  File "/Users/home/Code/python.homemedia_api/venv/lib/python2.7/site-packages/flask_restplus/swagger.py", line 177, in as_dict
    paths[extract_path(url)] = self.serialize_resource(ns, resource, url, kwargs)
  File "/Users/home/Code/python.homemedia_api/venv/lib/python2.7/site-packages/flask_restplus/swagger.py", line 319, in serialize_resource
    path[method] = self.serialize_operation(doc, method)
  File "/Users/home/Code/python.homemedia_api/venv/lib/python2.7/site-packages/flask_restplus/swagger.py", line 325, in serialize_operation
    'responses': self.responses_for(doc, method) or None,
  File "/Users/home/Code/python.homemedia_api/venv/lib/python2.7/site-packages/flask_restplus/swagger.py", line 435, in responses_for
    responses[code]['schema'] = self.serialize_schema(model)
  File "/Users/home/Code/python.homemedia_api/venv/lib/python2.7/site-packages/flask_restplus/swagger.py", line 484, in serialize_schema
    self.register_model(model)
  File "/Users/home/Code/python.homemedia_api/venv/lib/python2.7/site-packages/flask_restplus/swagger.py", line 505, in register_model
    raise ValueError('Model {0} not registered'.format(name))
ValueError: Model folder_model not registered
2018-11-17 15:45:55,292 - [INFO] werkzeug [_internal, line 88]: 127.0.0.1 - - [17/Nov/2018 15:45:55] "GET /swagger.json HTTP/1.1" 500 -
2018-11-17 15:46:05,671 - [INFO] werkzeug [_internal, line 88]:  * Detected change in '/Users/home/Code/python.homemedia_api/src/api/data_models.py', reloading
2018-11-17 15:46:05,707 - [INFO] werkzeug [_internal, line 88]:  * Restarting with stat
2018-11-17 15:46:06,040 - [INFO] __main__ [app_api, line 43]: ================================================================
2018-11-17 15:46:06,040 - [INFO] __main__ [app_api, line 44]: ================================================================
2018-11-17 15:46:06,040 - [INFO] __main__ [app_api, line 45]: ================================================================
2018-11-17 15:46:06,041 - [INFO] __main__ [app_api, line 46]: Initialising app
2018-11-17 15:46:06,058 - [WARNING] werkzeug [_internal, line 88]:  * Debugger is active!
2018-11-17 15:46:06,091 - [INFO] werkzeug [_internal, line 88]:  * Debugger PIN: 449-218-456
2018-11-17 15:47:21,069 - [INFO] werkzeug [_internal, line 88]:  * Detected change in '/Users/home/Code/python.homemedia_api/src/api/data_models.py', reloading
2018-11-17 15:47:21,090 - [INFO] werkzeug [_internal, line 88]:  * Restarting with stat
2018-11-17 15:47:21,308 - [INFO] __main__ [app_api, line 43]: ================================================================
2018-11-17 15:47:21,308 - [INFO] __main__ [app_api, line 44]: ================================================================
2018-11-17 15:47:21,308 - [INFO] __main__ [app_api, line 45]: ================================================================
2018-11-17 15:47:21,308 - [INFO] __main__ [app_api, line 46]: Initialising app
2018-11-17 15:47:21,316 - [WARNING] werkzeug [_internal, line 88]:  * Debugger is active!
2018-11-17 15:47:21,330 - [INFO] werkzeug [_internal, line 88]:  * Debugger PIN: 449-218-456
2018-11-17 15:47:34,511 - [INFO] werkzeug [_internal, line 88]:  * Detected change in '/Users/home/Code/python.homemedia_api/venv/lib/python2.7/site-packages/flask_restplus/representations.py', reloading
2018-11-17 15:47:34,567 - [INFO] werkzeug [_internal, line 88]:  * Restarting with stat
2018-11-17 15:47:35,370 - [INFO] __main__ [app_api, line 43]: ================================================================
2018-11-17 15:47:35,370 - [INFO] __main__ [app_api, line 44]: ================================================================
2018-11-17 15:47:35,370 - [INFO] __main__ [app_api, line 45]: ================================================================
2018-11-17 15:47:35,370 - [INFO] __main__ [app_api, line 46]: Initialising app
2018-11-17 15:47:35,399 - [WARNING] werkzeug [_internal, line 88]:  * Debugger is active!
2018-11-17 15:47:35,443 - [INFO] werkzeug [_internal, line 88]:  * Debugger PIN: 449-218-456
2018-11-17 15:47:42,349 - [INFO] __main__ [app_api, line 43]: ================================================================
2018-11-17 15:47:42,349 - [INFO] __main__ [app_api, line 44]: ================================================================
2018-11-17 15:47:42,349 - [INFO] __main__ [app_api, line 45]: ================================================================
2018-11-17 15:47:42,349 - [INFO] __main__ [app_api, line 46]: Initialising app
2018-11-17 15:47:42,371 - [INFO] werkzeug [_internal, line 88]:  * Running on http://127.0.0.1:6500/ (Press CTRL+C to quit)
2018-11-17 15:47:42,372 - [INFO] werkzeug [_internal, line 88]:  * Restarting with stat
2018-11-17 15:47:42,687 - [INFO] __main__ [app_api, line 43]: ================================================================
2018-11-17 15:47:42,687 - [INFO] __main__ [app_api, line 44]: ================================================================
2018-11-17 15:47:42,687 - [INFO] __main__ [app_api, line 45]: ================================================================
2018-11-17 15:47:42,687 - [INFO] __main__ [app_api, line 46]: Initialising app
2018-11-17 15:47:42,696 - [WARNING] werkzeug [_internal, line 88]:  * Debugger is active!
2018-11-17 15:47:42,709 - [INFO] werkzeug [_internal, line 88]:  * Debugger PIN: 449-218-456
2018-11-17 15:47:44,953 - [INFO] werkzeug [_internal, line 88]: 127.0.0.1 - - [17/Nov/2018 15:47:44] "GET / HTTP/1.1" 200 -
2018-11-17 15:47:45,357 - [ERROR] flask_restplus.api [api, line 488]: Unable to render schema
Traceback (most recent call last):
  File "/Users/home/Code/python.homemedia_api/venv/lib/python2.7/site-packages/flask_restplus/api.py", line 483, in __schema__
    self._schema = Swagger(self).as_dict()
  File "/Users/home/Code/python.homemedia_api/venv/lib/python2.7/site-packages/flask_restplus/swagger.py", line 177, in as_dict
    paths[extract_path(url)] = self.serialize_resource(ns, resource, url, kwargs)
  File "/Users/home/Code/python.homemedia_api/venv/lib/python2.7/site-packages/flask_restplus/swagger.py", line 346, in serialize_resource
    path[method] = self.serialize_operation(doc, method)
  File "/Users/home/Code/python.homemedia_api/venv/lib/python2.7/site-packages/flask_restplus/swagger.py", line 352, in serialize_operation
    'responses': self.responses_for(doc, method) or None,
  File "/Users/home/Code/python.homemedia_api/venv/lib/python2.7/site-packages/flask_restplus/swagger.py", line 464, in responses_for
    responses[code]['schema'] = self.serialize_schema(model)
  File "/Users/home/Code/python.homemedia_api/venv/lib/python2.7/site-packages/flask_restplus/swagger.py", line 513, in serialize_schema
    self.register_model(model)
  File "/Users/home/Code/python.homemedia_api/venv/lib/python2.7/site-packages/flask_restplus/swagger.py", line 534, in register_model
    raise ValueError('Model {0} not registered'.format(name))
ValueError: Model folder_model not registered
2018-11-17 15:47:45,359 - [INFO] werkzeug [_internal, line 88]: 127.0.0.1 - - [17/Nov/2018 15:47:45] "GET /swagger.json HTTP/1.1" 500 -
2018-11-17 15:47:45,383 - [INFO] werkzeug [_internal, line 88]: 127.0.0.1 - - [17/Nov/2018 15:47:45] "GET /swaggerui/favicon-32x32.png HTTP/1.1" 200 -
2018-11-17 15:50:15,763 - [INFO] werkzeug [_internal, line 88]:  * Detected change in '/Users/home/Code/python.homemedia_api/src/api/data_models.py', reloading
2018-11-17 15:50:15,782 - [INFO] werkzeug [_internal, line 88]:  * Restarting with stat
2018-11-17 15:50:16,047 - [INFO] __main__ [app_api, line 43]: ================================================================
2018-11-17 15:50:16,048 - [INFO] __main__ [app_api, line 44]: ================================================================
2018-11-17 15:50:16,048 - [INFO] __main__ [app_api, line 45]: ================================================================
2018-11-17 15:50:16,048 - [INFO] __main__ [app_api, line 46]: Initialising app
2018-11-17 15:50:16,069 - [WARNING] werkzeug [_internal, line 88]:  * Debugger is active!
2018-11-17 15:50:16,083 - [INFO] werkzeug [_internal, line 88]:  * Debugger PIN: 449-218-456
2018-11-17 15:50:19,876 - [INFO] werkzeug [_internal, line 88]: 127.0.0.1 - - [17/Nov/2018 15:50:19] "GET / HTTP/1.1" 200 -
2018-11-17 15:50:20,294 - [ERROR] flask_restplus.api [api, line 488]: Unable to render schema
Traceback (most recent call last):
  File "/Users/home/Code/python.homemedia_api/venv/lib/python2.7/site-packages/flask_restplus/api.py", line 483, in __schema__
    self._schema = Swagger(self).as_dict()
  File "/Users/home/Code/python.homemedia_api/venv/lib/python2.7/site-packages/flask_restplus/swagger.py", line 177, in as_dict
    paths[extract_path(url)] = self.serialize_resource(ns, resource, url, kwargs)
  File "/Users/home/Code/python.homemedia_api/venv/lib/python2.7/site-packages/flask_restplus/swagger.py", line 346, in serialize_resource
    path[method] = self.serialize_operation(doc, method)
  File "/Users/home/Code/python.homemedia_api/venv/lib/python2.7/site-packages/flask_restplus/swagger.py", line 352, in serialize_operation
    'responses': self.responses_for(doc, method) or None,
  File "/Users/home/Code/python.homemedia_api/venv/lib/python2.7/site-packages/flask_restplus/swagger.py", line 464, in responses_for
    responses[code]['schema'] = self.serialize_schema(model)
  File "/Users/home/Code/python.homemedia_api/venv/lib/python2.7/site-packages/flask_restplus/swagger.py", line 513, in serialize_schema
    self.register_model(model)
  File "/Users/home/Code/python.homemedia_api/venv/lib/python2.7/site-packages/flask_restplus/swagger.py", line 534, in register_model
    raise ValueError('Model {0} not registered'.format(name))
ValueError: Model folder_model not registered
2018-11-17 15:50:20,298 - [INFO] werkzeug [_internal, line 88]: 127.0.0.1 - - [17/Nov/2018 15:50:20] "GET /swagger.json HTTP/1.1" 500 -
2018-11-17 15:50:20,337 - [INFO] werkzeug [_internal, line 88]: 127.0.0.1 - - [17/Nov/2018 15:50:20] "GET /swaggerui/favicon-32x32.png HTTP/1.1" 200 -
2018-11-17 15:53:24,555 - [INFO] werkzeug [_internal, line 88]:  * Detected change in '/Users/home/Code/python.homemedia_api/src/api/endpoints/ns_browse.py', reloading
2018-11-17 15:53:24,591 - [INFO] werkzeug [_internal, line 88]:  * Restarting with stat
2018-11-17 15:53:25,379 - [INFO] __main__ [app_api, line 43]: ================================================================
2018-11-17 15:53:25,379 - [INFO] __main__ [app_api, line 44]: ================================================================
2018-11-17 15:53:25,379 - [INFO] __main__ [app_api, line 45]: ================================================================
2018-11-17 15:53:25,379 - [INFO] __main__ [app_api, line 46]: Initialising app
2018-11-17 15:53:25,388 - [WARNING] werkzeug [_internal, line 88]:  * Debugger is active!
2018-11-17 15:53:25,402 - [INFO] werkzeug [_internal, line 88]:  * Debugger PIN: 449-218-456
2018-11-17 15:53:31,823 - [INFO] werkzeug [_internal, line 88]: 127.0.0.1 - - [17/Nov/2018 15:53:31] "GET / HTTP/1.1" 200 -
2018-11-17 15:53:32,217 - [ERROR] flask_restplus.api [api, line 488]: Unable to render schema
Traceback (most recent call last):
  File "/Users/home/Code/python.homemedia_api/venv/lib/python2.7/site-packages/flask_restplus/api.py", line 483, in __schema__
    self._schema = Swagger(self).as_dict()
  File "/Users/home/Code/python.homemedia_api/venv/lib/python2.7/site-packages/flask_restplus/swagger.py", line 177, in as_dict
    paths[extract_path(url)] = self.serialize_resource(ns, resource, url, kwargs)
  File "/Users/home/Code/python.homemedia_api/venv/lib/python2.7/site-packages/flask_restplus/swagger.py", line 346, in serialize_resource
    path[method] = self.serialize_operation(doc, method)
  File "/Users/home/Code/python.homemedia_api/venv/lib/python2.7/site-packages/flask_restplus/swagger.py", line 352, in serialize_operation
    'responses': self.responses_for(doc, method) or None,
  File "/Users/home/Code/python.homemedia_api/venv/lib/python2.7/site-packages/flask_restplus/swagger.py", line 464, in responses_for
    responses[code]['schema'] = self.serialize_schema(model)
  File "/Users/home/Code/python.homemedia_api/venv/lib/python2.7/site-packages/flask_restplus/swagger.py", line 513, in serialize_schema
    self.register_model(model)
  File "/Users/home/Code/python.homemedia_api/venv/lib/python2.7/site-packages/flask_restplus/swagger.py", line 534, in register_model
    raise ValueError('Model {0} not registered'.format(name))
ValueError: Model init_model not registered
2018-11-17 15:53:32,220 - [INFO] werkzeug [_internal, line 88]: 127.0.0.1 - - [17/Nov/2018 15:53:32] "GET /swagger.json HTTP/1.1" 500 -
2018-11-17 15:53:32,242 - [INFO] werkzeug [_internal, line 88]: 127.0.0.1 - - [17/Nov/2018 15:53:32] "GET /swaggerui/favicon-32x32.png HTTP/1.1" 200 -
2018-11-17 15:53:43,654 - [INFO] werkzeug [_internal, line 88]:  * Detected change in '/Users/home/Code/python.homemedia_api/src/api/endpoints/ns_init.py', reloading
2018-11-17 15:53:43,715 - [INFO] werkzeug [_internal, line 88]:  * Restarting with stat
2018-11-17 15:53:44,215 - [INFO] __main__ [app_api, line 43]: ================================================================
2018-11-17 15:53:44,215 - [INFO] __main__ [app_api, line 44]: ================================================================
2018-11-17 15:53:44,215 - [INFO] __main__ [app_api, line 45]: ================================================================
2018-11-17 15:53:44,215 - [INFO] __main__ [app_api, line 46]: Initialising app
2018-11-17 15:53:44,226 - [WARNING] werkzeug [_internal, line 88]:  * Debugger is active!
2018-11-17 15:53:44,240 - [INFO] werkzeug [_internal, line 88]:  * Debugger PIN: 449-218-456
2018-11-17 15:53:45,505 - [INFO] werkzeug [_internal, line 88]: 127.0.0.1 - - [17/Nov/2018 15:53:45] "GET / HTTP/1.1" 200 -
2018-11-17 15:53:45,989 - [INFO] werkzeug [_internal, line 88]: 127.0.0.1 - - [17/Nov/2018 15:53:45] "GET /swagger.json HTTP/1.1" 200 -
2018-11-17 15:53:46,010 - [INFO] werkzeug [_internal, line 88]: 127.0.0.1 - - [17/Nov/2018 15:53:46] "GET /swaggerui/favicon-32x32.png HTTP/1.1" 200 -
2018-11-17 15:54:25,870 - [INFO] werkzeug [_internal, line 88]:  * Detected change in '/Users/home/Code/python.homemedia_api/src/api/endpoints/ns_init.py', reloading
2018-11-17 15:54:25,890 - [INFO] werkzeug [_internal, line 88]:  * Restarting with stat
2018-11-17 15:54:26,238 - [INFO] __main__ [app_api, line 43]: ================================================================
2018-11-17 15:54:26,238 - [INFO] __main__ [app_api, line 44]: ================================================================
2018-11-17 15:54:26,238 - [INFO] __main__ [app_api, line 45]: ================================================================
2018-11-17 15:54:26,239 - [INFO] __main__ [app_api, line 46]: Initialising app
2018-11-17 15:54:26,293 - [WARNING] werkzeug [_internal, line 88]:  * Debugger is active!
2018-11-17 15:54:26,344 - [INFO] werkzeug [_internal, line 88]:  * Debugger PIN: 449-218-456
2018-11-17 15:54:27,443 - [INFO] werkzeug [_internal, line 88]: 127.0.0.1 - - [17/Nov/2018 15:54:27] "GET / HTTP/1.1" 200 -
2018-11-17 15:54:27,728 - [INFO] werkzeug [_internal, line 88]: 127.0.0.1 - - [17/Nov/2018 15:54:27] "GET /swagger.json HTTP/1.1" 200 -
2018-11-17 15:54:27,751 - [INFO] werkzeug [_internal, line 88]: 127.0.0.1 - - [17/Nov/2018 15:54:27] "GET /swaggerui/favicon-32x32.png HTTP/1.1" 200 -
2018-11-17 15:54:37,553 - [INFO] werkzeug [_internal, line 88]:  * Detected change in '/Users/home/Code/python.homemedia_api/src/api/endpoints/ns_browse.py', reloading
2018-11-17 15:54:37,644 - [INFO] werkzeug [_internal, line 88]:  * Restarting with stat
2018-11-17 15:54:38,382 - [INFO] __main__ [app_api, line 43]: ================================================================
2018-11-17 15:54:38,382 - [INFO] __main__ [app_api, line 44]: ================================================================
2018-11-17 15:54:38,383 - [INFO] __main__ [app_api, line 45]: ================================================================
2018-11-17 15:54:38,383 - [INFO] __main__ [app_api, line 46]: Initialising app
2018-11-17 15:54:38,394 - [WARNING] werkzeug [_internal, line 88]:  * Debugger is active!
2018-11-17 15:54:38,409 - [INFO] werkzeug [_internal, line 88]:  * Debugger PIN: 449-218-456
2018-11-17 15:54:39,212 - [INFO] werkzeug [_internal, line 88]: 127.0.0.1 - - [17/Nov/2018 15:54:39] "GET / HTTP/1.1" 200 -
2018-11-17 15:54:39,486 - [INFO] werkzeug [_internal, line 88]: 127.0.0.1 - - [17/Nov/2018 15:54:39] "GET /swagger.json HTTP/1.1" 200 -
2018-11-17 15:54:39,545 - [INFO] werkzeug [_internal, line 88]: 127.0.0.1 - - [17/Nov/2018 15:54:39] "GET /swaggerui/favicon-32x32.png HTTP/1.1" 200 -
2018-11-17 15:55:05,434 - [INFO] __main__ [app_api, line 43]: ================================================================
2018-11-17 15:55:05,434 - [INFO] __main__ [app_api, line 44]: ================================================================
2018-11-17 15:55:05,434 - [INFO] __main__ [app_api, line 45]: ================================================================
2018-11-17 15:55:05,434 - [INFO] __main__ [app_api, line 46]: Initialising app
2018-11-17 15:55:05,444 - [INFO] werkzeug [_internal, line 88]:  * Running on http://127.0.0.1:6500/ (Press CTRL+C to quit)
2018-11-17 15:55:05,445 - [INFO] werkzeug [_internal, line 88]:  * Restarting with stat
2018-11-17 15:55:05,661 - [INFO] __main__ [app_api, line 43]: ================================================================
2018-11-17 15:55:05,662 - [INFO] __main__ [app_api, line 44]: ================================================================
2018-11-17 15:55:05,662 - [INFO] __main__ [app_api, line 45]: ================================================================
2018-11-17 15:55:05,662 - [INFO] __main__ [app_api, line 46]: Initialising app
2018-11-17 15:55:05,677 - [WARNING] werkzeug [_internal, line 88]:  * Debugger is active!
2018-11-17 15:55:05,697 - [INFO] werkzeug [_internal, line 88]:  * Debugger PIN: 449-218-456
2018-11-17 15:55:07,428 - [INFO] werkzeug [_internal, line 88]: 127.0.0.1 - - [17/Nov/2018 15:55:07] "GET / HTTP/1.1" 200 -
2018-11-17 15:55:07,678 - [INFO] werkzeug [_internal, line 88]: 127.0.0.1 - - [17/Nov/2018 15:55:07] "GET /swagger.json HTTP/1.1" 200 -
2018-11-17 15:55:07,706 - [INFO] werkzeug [_internal, line 88]: 127.0.0.1 - - [17/Nov/2018 15:55:07] "GET /swaggerui/favicon-32x32.png HTTP/1.1" 200 -
2018-11-17 15:56:10,722 - [INFO] werkzeug [_internal, line 88]:  * Detected change in '/Users/home/Code/python.homemedia_api/src/api/data_models.py', reloading
2018-11-17 15:56:10,749 - [INFO] werkzeug [_internal, line 88]:  * Restarting with stat
2018-11-17 15:56:11,048 - [INFO] __main__ [app_api, line 43]: ================================================================
2018-11-17 15:56:11,048 - [INFO] __main__ [app_api, line 44]: ================================================================
2018-11-17 15:56:11,048 - [INFO] __main__ [app_api, line 45]: ================================================================
2018-11-17 15:56:11,048 - [INFO] __main__ [app_api, line 46]: Initialising app
2018-11-17 15:56:11,057 - [WARNING] werkzeug [_internal, line 88]:  * Debugger is active!
2018-11-17 15:56:11,071 - [INFO] werkzeug [_internal, line 88]:  * Debugger PIN: 449-218-456
2018-11-17 15:56:14,120 - [INFO] werkzeug [_internal, line 88]:  * Detected change in '/Users/home/Code/python.homemedia_api/src/api/data_models.py', reloading
2018-11-17 15:56:14,162 - [INFO] werkzeug [_internal, line 88]:  * Restarting with stat
2018-11-17 15:56:14,420 - [INFO] __main__ [app_api, line 43]: ================================================================
2018-11-17 15:56:14,420 - [INFO] __main__ [app_api, line 44]: ================================================================
2018-11-17 15:56:14,421 - [INFO] __main__ [app_api, line 45]: ================================================================
2018-11-17 15:56:14,421 - [INFO] __main__ [app_api, line 46]: Initialising app
2018-11-17 15:56:14,429 - [WARNING] werkzeug [_internal, line 88]:  * Debugger is active!
2018-11-17 15:56:14,443 - [INFO] werkzeug [_internal, line 88]:  * Debugger PIN: 449-218-456
2018-11-17 15:56:16,557 - [INFO] werkzeug [_internal, line 88]: 127.0.0.1 - - [17/Nov/2018 15:56:16] "GET / HTTP/1.1" 200 -
2018-11-17 15:56:16,813 - [INFO] werkzeug [_internal, line 88]: 127.0.0.1 - - [17/Nov/2018 15:56:16] "GET /swagger.json HTTP/1.1" 200 -
2018-11-17 15:56:16,844 - [INFO] werkzeug [_internal, line 88]: 127.0.0.1 - - [17/Nov/2018 15:56:16] "GET /swaggerui/favicon-32x32.png HTTP/1.1" 200 -
2018-11-17 15:56:39,226 - [DEBUG] api.endpoints.ns_browse [ns_browse, line 48]: {'path': '_inbox', 'include_assets': True, 'flatten_folders': False, 'include_folders': True}
2018-11-17 15:56:39,252 - [INFO] werkzeug [_internal, line 88]: 127.0.0.1 - - [17/Nov/2018 15:56:39] "GET /browse?path=_inbox&include_assets=true&flatten_folders=false HTTP/1.1" 200 -
2018-11-17 15:56:39,382 - [DEBUG] api.endpoints.ns_preview [ns_preview, line 45]: {'path': '_inbox/canon_7d2.2018-07-01.038A5075.jpg', 'max_quality': True, 'cache_bust': 'False'}
2018-11-17 15:56:39,389 - [INFO] werkzeug [_internal, line 88]: 127.0.0.1 - - [17/Nov/2018 15:56:39] "GET /preview?path=_inbox/canon_7d2.2018-07-01.038A5075.jpg&max_quality=true HTTP/1.1" 200 -
2018-11-17 16:01:25,882 - [INFO] __main__ [app_api, line 43]: ================================================================
2018-11-17 16:01:25,882 - [INFO] __main__ [app_api, line 44]: ================================================================
2018-11-17 16:01:25,882 - [INFO] __main__ [app_api, line 45]: ================================================================
2018-11-17 16:01:25,882 - [INFO] __main__ [app_api, line 46]: Initialising app
2018-11-17 16:01:25,893 - [INFO] werkzeug [_internal, line 88]:  * Running on http://127.0.0.1:6500/ (Press CTRL+C to quit)
2018-11-17 16:01:25,893 - [INFO] werkzeug [_internal, line 88]:  * Restarting with stat
2018-11-17 16:01:26,151 - [INFO] __main__ [app_api, line 43]: ================================================================
2018-11-17 16:01:26,151 - [INFO] __main__ [app_api, line 44]: ================================================================
2018-11-17 16:01:26,151 - [INFO] __main__ [app_api, line 45]: ================================================================
2018-11-17 16:01:26,151 - [INFO] __main__ [app_api, line 46]: Initialising app
2018-11-17 16:01:26,160 - [WARNING] werkzeug [_internal, line 88]:  * Debugger is active!
2018-11-17 16:01:26,174 - [INFO] werkzeug [_internal, line 88]:  * Debugger PIN: 449-218-456
2018-11-17 16:01:28,381 - [INFO] werkzeug [_internal, line 88]: 127.0.0.1 - - [17/Nov/2018 16:01:28] "GET / HTTP/1.1" 200 -
2018-11-17 16:01:28,863 - [INFO] werkzeug [_internal, line 88]: 127.0.0.1 - - [17/Nov/2018 16:01:28] "GET /swagger.json HTTP/1.1" 200 -
2018-11-17 16:01:36,396 - [DEBUG] api.endpoints.ns_browse [ns_browse, line 48]: {'path': '', 'include_assets': True, 'flatten_folders': False, 'include_folders': True}
2018-11-17 16:01:36,396 - [INFO] api.core.utils_fs [utils_fs, line 227]: Blacklisted folder: /Users/Home/Pictures/@eadir
2018-11-17 16:01:36,396 - [INFO] api.core.utils_fs [utils_fs, line 227]: Blacklisted folder: /Users/Home/Pictures/.TEST
2018-11-17 16:01:36,397 - [INFO] api.core.utils_fs [utils_fs, line 254]: Blacklisted folder: /Users/Home/Pictures/@eadir
2018-11-17 16:01:36,397 - [INFO] api.core.utils_fs [utils_fs, line 254]: Blacklisted folder: /Users/Home/Pictures/.TEST
2018-11-17 16:01:36,415 - [INFO] api.core.utils_fs [utils_fs, line 227]: Blacklisted folder: /Users/Home/Pictures/ORIGINALS/Lightroom
2018-11-17 16:01:36,416 - [INFO] werkzeug [_internal, line 88]: 127.0.0.1 - - [17/Nov/2018 16:01:36] "GET /browse?include_folders=true&include_assets=true&flatten_folders=false HTTP/1.1" 200 -
